Workbook
Name LIST_THERAPIST: VALIDATION!$D$2:$D$5
Name LIST_SERVICE: VALIDATION!$C$2:$C$92
Name LIST_AREA: VALIDATION!$F$2:$F$4
Name LIST_BOOKING_TYPE: VALIDATION!$A$2:$A$3
Name LIST_STATUS: VALIDATION!$B$2:$B$5
Name LIST_PAYMENT: VALIDATION!$E$2:$E$4
Name LIST_PROMO: VALIDATION!$G$2:$G$6

Sheet LOGIN
B1: DASHBOARD | D1: INPUT | F1: LOG | H1: CRM | J1: HARIAN | L1: BULANAN | N1: INVOICE | P1: JADWAL | R1: LOGIN
B6: Nama Email | C6: puguh.legowo.k@gmail.com | E6: PIN | F6: 1234 | H6: LOGIN
B8: Role | C8: OWNER | E8: Status | F8: LOGIN OK | H8: LOGOUT
B9: Tanggal Login | C9: 46107.78

Sheet START HERE
B2: START HERE - 5 LANGKAH CEPAT (VERSI PREMIUM)
B4: No | C4: Langkah
B5: 1 | C5: Pilih Menu SmartSpaDash Premium, klik Otorisasi Akun Google
B6: 2 | C6: Login di sheet login
B7: 3 | C7: Isi semua master layanan, terapis, SA ( Sheet Warna Kuning )
B8: 4 | C8: Input Booking
B9: 5 | C9: Pantau hasil di DASHBOARD, JADWAL HARIAN, REKAP, dan KOMISI TERAPIS.

Sheet DASHBOARD V2
B1: DASHBOARD | D1: INPUT | F1: LOG | H1: CRM | J1: HARIAN | L1: BULANAN | N1: INVOICE | P1: JADWAL | R1: LOGIN
B5: Tahun | C5: Semua Tahun | E5: Bulan | F5: Maret | H5: Hari | I5: Semua Hari | K5: RESET FILTER
B7: Total Booking Closed | E7: Omzet Closed | H7: Homecare Closed
B8: ='DASHBOARD V2 DATA'!$S$2 -> 4 | E8: ='DASHBOARD V2 DATA'!$T$2 -> 370000 | H8: ='DASHBOARD V2 DATA'!$U$2 -> 1
B12: Inhouse Closed | E12: Avg Ticket Closed | H12: Filter Aktif
B13: ='DASHBOARD V2 DATA'!$V$2 -> 3 | E13: ='DASHBOARD V2 DATA'!$W$2 -> 92500 | H13: =IF(C5="Semua Tahun","Semua Tahun",C5)&" | "&IF(F5="Semua Bulan","Semua Bulan",F5)&" | "&IF(I5="Semua Hari","Semua Hari",I5) -> Semua Tahun | Maret | Semua Hari
B18: Filter Ringkas | E18: 10 Layanan Terlaris (Closed Booking)
B19: Year | C19: =C5 -> Semua Tahun | E19: Ranking | F19: Layanan | G19: Category | H19: Inhouse/Homecare | I19: Jumlah Booking
B20: Month | C20: =F5 -> Maret | E20: =IF('DASHBOARD V2 DATA'!$A$2="" ,"" ,'DASHBOARD V2 DATA'!$A$2) -> 1 | F20: =IF($E20="" ,"" ,'DASHBOARD V2 DATA'!$B$2) -> Colic Relief Massage Baby (Pijat Kolik) | G20: =IF($E20="" ,"" ,'DASHBOARD V2 DATA'!$C$2) -> BABY | H20: =IF($E20="" ,"" ,'DASHBOARD V2 DATA'!$D$2) -> Inhouse | I20: =IF($E20="" ,"" ,'DASHBOARD V2 DATA'!$E$2) -> 1
B21: Day | C21: =I5 -> Semua Hari | E21: =IF('DASHBOARD V2 DATA'!$A$3="" ,"" ,'DASHBOARD V2 DATA'!$A$3) -> 2 | F21: =IF($E21="" ,"" ,'DASHBOARD V2 DATA'!$B$3) -> Healthy Breath Package (Paket Nafas Sehat) | G21: =IF($E21="" ,"" ,'DASHBOARD V2 DATA'!$C$3) -> BABY | H21: =IF($E21="" ,"" ,'DASHBOARD V2 DATA'!$D$3) -> Inhouse | I21: =IF($E21="" ,"" ,'DASHBOARD V2 DATA'!$E$3) -> 1
E22: =IF('DASHBOARD V2 DATA'!$A$4="" ,"" ,'DASHBOARD V2 DATA'!$A$4) -> 3 | F22: =IF($E22="" ,"" ,'DASHBOARD V2 DATA'!$B$4) -> Newborn Starter Pack With Piercing (Paket Awal Kehidupan) | G22: =IF($E22="" ,"" ,'DASHBOARD V2 DATA'!$C$4) -> BABY | H22: =IF($E22="" ,"" ,'DASHBOARD V2 DATA'!$D$4) -> Inhouse | I22: =IF($E22="" ,"" ,'DASHBOARD V2 DATA'!$E$4) -> 1
E23: =IF('DASHBOARD V2 DATA'!$A$5="" ,"" ,'DASHBOARD V2 DATA'!$A$5) -> 4 | F23: =IF($E23="" ,"" ,'DASHBOARD V2 DATA'!$B$5) -> Oxytocin Stimulation Massage HC (Pijat Oksitosin) | G23: =IF($E23="" ,"" ,'DASHBOARD V2 DATA'!$C$5) -> HOMECARE MOM | H23: =IF($E23="" ,"" ,'DASHBOARD V2 DATA'!$D$5) -> Homecare | I23: =IF($E23="" ,"" ,'DASHBOARD V2 DATA'!$E$5) -> 1
E24: =IF('DASHBOARD V2 DATA'!$A$6="" ,"" ,'DASHBOARD V2 DATA'!$A$6) | F24: =IF($E24="" ,"" ,'DASHBOARD V2 DATA'!$B$6) | G24: =IF($E24="" ,"" ,'DASHBOARD V2 DATA'!$C$6) | H24: =IF($E24="" ,"" ,'DASHBOARD V2 DATA'!$D$6) | I24: =IF($E24="" ,"" ,'DASHBOARD V2 DATA'!$E$6)
E25: =IF('DASHBOARD V2 DATA'!$A$7="" ,"" ,'DASHBOARD V2 DATA'!$A$7) | F25: =IF($E25="" ,"" ,'DASHBOARD V2 DATA'!$B$7) | G25: =IF($E25="" ,"" ,'DASHBOARD V2 DATA'!$C$7) | H25: =IF($E25="" ,"" ,'DASHBOARD V2 DATA'!$D$7) | I25: =IF($E25="" ,"" ,'DASHBOARD V2 DATA'!$E$7)
E26: =IF('DASHBOARD V2 DATA'!$A$8="" ,"" ,'DASHBOARD V2 DATA'!$A$8) | F26: =IF($E26="" ,"" ,'DASHBOARD V2 DATA'!$B$8) | G26: =IF($E26="" ,"" ,'DASHBOARD V2 DATA'!$C$8) | H26: =IF($E26="" ,"" ,'DASHBOARD V2 DATA'!$D$8) | I26: =IF($E26="" ,"" ,'DASHBOARD V2 DATA'!$E$8)
E27: =IF('DASHBOARD V2 DATA'!$A$9="" ,"" ,'DASHBOARD V2 DATA'!$A$9) | F27: =IF($E27="" ,"" ,'DASHBOARD V2 DATA'!$B$9) | G27: =IF($E27="" ,"" ,'DASHBOARD V2 DATA'!$C$9) | H27: =IF($E27="" ,"" ,'DASHBOARD V2 DATA'!$D$9) | I27: =IF($E27="" ,"" ,'DASHBOARD V2 DATA'!$E$9)
E28: =IF('DASHBOARD V2 DATA'!$A$10="" ,"" ,'DASHBOARD V2 DATA'!$A$10) | F28: =IF($E28="" ,"" ,'DASHBOARD V2 DATA'!$B$10) | G28: =IF($E28="" ,"" ,'DASHBOARD V2 DATA'!$C$10) | H28: =IF($E28="" ,"" ,'DASHBOARD V2 DATA'!$D$10) | I28: =IF($E28="" ,"" ,'DASHBOARD V2 DATA'!$E$10)
E29: =IF('DASHBOARD V2 DATA'!$A$11="" ,"" ,'DASHBOARD V2 DATA'!$A$11) | F29: =IF($E29="" ,"" ,'DASHBOARD V2 DATA'!$B$11) | G29: =IF($E29="" ,"" ,'DASHBOARD V2 DATA'!$C$11) | H29: =IF($E29="" ,"" ,'DASHBOARD V2 DATA'!$D$11) | I29: =IF($E29="" ,"" ,'DASHBOARD V2 DATA'!$E$11)
B31: Trend Omzet Closed | J31: Trend Booking Closed | R31: Homecare vs Inhouse
B60: Dashboard V2 mengambil omzet hanya dari payment_status = Lunas dan service_done_status = DONE.

Sheet INPUT BOOKING
B1: DASHBOARD | D1: INPUT | F1: LOG | H1: CRM | J1: HARIAN | L1: BULANAN | N1: INVOICE | P1: JADWAL | R1: LOGIN
C4: PILIH TANGGAL BOOKING: | D4: BULAN | E4: TAHUN
B5: INFORMASI BOOKING | C5: 26 | D5: 3 | E5: 2026 | H5: RINGKASAN PEMBAYARAN | J5: HASIL BOOKING | K5: HASIL CARI
B6: Tanggal Booking | C6: =D5&"/"&C5&"/"&E5 -> 3/26/2026 | E6: Jenis Booking | H6: Kode Booking Aktif
B7: Terapis | E7: Status Booking | H7: Kategori | J7: {=IFERROR(XLOOKUP(C8,MASTER_LAYANAN!$C:$C,MASTER_LAYANAN!$B:$B,""),"")}
B8: Layanan | E8: Area Homecare | H8: Durasi (menit) | J8: {=IFERROR(XLOOKUP(C8,MASTER_LAYANAN!$C:$C,MASTER_LAYANAN!$D:$D,0),0)} -> 0
B9: Jam Mulai | E9: Promo / Diskon | H9: Harga Layanan | J9: {=IFERROR(XLOOKUP(C8,MASTER_LAYANAN!$C:$C,MASTER_LAYANAN!$E:$E,0),0)} -> 0
H10: Nilai Diskon | J10: {=IFERROR(IF(F9="","",IF(XLOOKUP(F9,MASTER_PROMO!$A:$A,MASTER_PROMO!$C:$C,"")="PERCENT",J9*XLOOKUP(F9,MASTER_PROMO!$A:$A,MASTER_PROMO!$D:$D,0)/100,_xludf.XLOOKUP(F9,MASTER_PROMO!$A:$A,MASTER_PROMO!$D:$D,0))),0)}
B11: DATA PELANGGAN | H11: Biaya Transport | J11: {=IF(F6="Homecare",IFERROR(XLOOKUP(F8,MASTER_HOMECARE!$A:$A,MASTER_HOMECARE!$C:$C,0),0),0)} -> 0
B12: Nama Mama / Ortu | E12: No WhatsApp | H12: Grand Total | J12: =J9-J10+J11 -> 0
B13: Nama Anak | E13: Usia Anak/ Mama | H13: Fee Terapis | J13: {=IFERROR(XLOOKUP(C8,MASTER_LAYANAN!$C:$C,MASTER_LAYANAN!$F:$F,0),0)*1000} -> 0
B14: Alamat | E14: Berat Anak/ Mama | H14: Fee Admin | J14: {=IFERROR(XLOOKUP(C8,MASTER_LAYANAN!$C:$C,MASTER_LAYANAN!$G:$G,0),0)*1000} -> 0
B15: Catatan Booking | E15: Metode Bayar | H15: Sisa Bayar | J15: =MAX(0,J12-C16) -> 0
B16: Deposit | E16: Cari Booking / WA | H16: Nama Ibu / Ortu
H17: Tanggal Booking
B18: KODE BOOKING BELUM LUNAS / BELUM SELESAI | H18: SIMPAN BOOKING | J18: RESET FORM
B19: Booking_ID | C19: Payment_Status | D19: service_done status
H20: CEK BENTROK | J20: CARI BOOKING
H22: BATAL DONE /LUNAS | J22: BUAT INVOICE
H24: TANDAI LUNAS | J24: TANDAI SELESAI
H26: Panduan Cepat | J26: Isi No WA / kode booking di F16 lalu klik Cari Booking. J22/H24/J24 akan memproses hasil di K6:K17.
H27: Status Sistem | J27: SmartSpaDash : Form berhasil di-reset.

Sheet JADWAL HARIAN
B1: DASHBOARD | D1: INPUT | F1: LOG | H1: CRM | J1: HARIAN | L1: BULANAN | N1: INVOICE | P1: JADWAL | R1: LOGIN
D4: PILIH TANGGAL | E4: PILIH BULAN | F4: PILIH TAHUN
B5: Tanggal Jadwal | C5: =D5&"-"&E5&"-"&F5 -> 26-3-2026 | D5: 26 | E5: 3 | F5: 2026
B7: Jam | C7: =IF(MASTER_TERAPIS!D2="YA",MASTER_TERAPIS!B2) -> bababab | D7: =IF(MASTER_TERAPIS!D3="YA",MASTER_TERAPIS!B3) -> Caccaca | E7: =IF(MASTER_TERAPIS!D4="YA",MASTER_TERAPIS!B4) -> ggagaga | F7: =IF(MASTER_TERAPIS!D5="YA",MASTER_TERAPIS!B5) -> hahaha | G7: =IF(MASTER_TERAPIS!D6="YA",MASTER_TERAPIS!B6) -> FALSE | H7: =IF(MASTER_TERAPIS!D7="YA",MASTER_TERAPIS!B7) -> FALSE
B8: 0.33333333 | C8: {=IFERROR(INDEX(TRANSAKSI_LOG!$M$2:$M$998,MATCH(1,INDEX((TRANSAKSI_LOG!$C$2:$C$998=$C$5)*(TRANSAKSI_LOG!$J$2:$J$998=C$7)*(TRANSAKSI_LOG!$E$2:$E$998<=$B8)*(TRANSAKSI_LOG!$F$2:$F$998>=$B8),0),0)) & " - " & INDEX(TRANSAKSI_LOG!$H$2:$H$998,MATCH(1,INDEX((TRANSAKSI_LOG!$C$2:$C$998=$C$5)*(TRANSAKSI_LOG!$J$2:$J$998=C$7)*(TRANSAKSI_LOG!$E$2:$E$998<=$B8)*(TRANSAKSI_LOG!$F$2:$F$998>=$B8),0),0)),"")} | D8: {=IFERROR(INDEX(TRANSAKSI_LOG!$M$2:$M$998,MATCH(1,INDEX((TRANSAKSI_LOG!$C$2:$C$998=$C$5)*(TRANSAKSI_LOG!$J$2:$J$998=D$7)*(TRANSAKSI_LOG!$E$2:$E$998<=$B8)*(TRANSAKSI_LOG!$F$2:$F$998>=$B8),0),0)) & " - " & INDEX(TRANSAKSI_LOG!$H$2:$H$998,MATCH(1,INDEX((TRANSAKSI_LOG!$C$2:$C$998=$C$5)*(TRANSAKSI_LOG!$J$2:$J$998=D$7)*(TRANSAKSI_LOG!$E$2:$E$998<=$B8)*(TRANSAKSI_LOG!$F$2:$F$998>=$B8),0),0)),"")} | E8: {=IFERROR(INDEX(TRANSAKSI_LOG!$M$2:$M$998,MATCH(1,INDEX((TRANSAKSI_LOG!$C$2:$C$998=$C$5)*(TRANSAKSI_LOG!$J$2:$J$998=E$7)*(TRANSAKSI_LOG!$E$2:$E$998<=$B8)*(TRANSAKSI_LOG!$F$2:$F$998>=$B8),0),0)) & " - " & INDEX(TRANSAKSI_LOG!$H$2:$H$998,MATCH(1,INDEX((TRANSAKSI_LOG!$C$2:$C$998=$C$5)*(TRANSAKSI_LOG!$J$2:$J$998=E$7)*(TRANSAKSI_LOG!$E$2:$E$998<=$B8)*(TRANSAKSI_LOG!$F$2:$F$998>=$B8),0),0)),"")} | F8: {=IFERROR(INDEX(TRANSAKSI_LOG!$M$2:$M$998,MATCH(1,INDEX((TRANSAKSI_LOG!$C$2:$C$998=$C$5)*(TRANSAKSI_LOG!$J$2:$J$998=F$7)*(TRANSAKSI_LOG!$E$2:$E$998<=$B8)*(TRANSAKSI_LOG!$F$2:$F$998>=$B8),0),0)) & " - " & INDEX(TRANSAKSI_LOG!$H$2:$H$998,MATCH(1,INDEX((TRANSAKSI_LOG!$C$2:$C$998=$C$5)*(TRANSAKSI_LOG!$J$2:$J$998=F$7)*(TRANSAKSI_LOG!$E$2:$E$998<=$B8)*(TRANSAKSI_LOG!$F$2:$F$998>=$B8),0),0)),"")} | G8: {=IFERROR(INDEX(TRANSAKSI_LOG!$M$2:$M$998,MATCH(1,INDEX((TRANSAKSI_LOG!$C$2:$C$998=$C$5)*(TRANSAKSI_LOG!$J$2:$J$998=G$7)*(TRANSAKSI_LOG!$E$2:$E$998<=$B8)*(TRANSAKSI_LOG!$F$2:$F$998>=$B8),0),0)) & " - " & INDEX(TRANSAKSI_LOG!$H$2:$H$998,MATCH(1,INDEX((TRANSAKSI_LOG!$C$2:$C$998=$C$5)*(TRANSAKSI_LOG!$J$2:$J$998=G$7)*(TRANSAKSI_LOG!$E$2:$E$998<=$B8)*(TRANSAKSI_LOG!$F$2:$F$998>=$B8),0),0)),"")} | H8: {=IFERROR(INDEX(TRANSAKSI_LOG!$M$2:$M$998,MATCH(1,INDEX((TRANSAKSI_LOG!$C$2:$C$998=$C$5)*(TRANSAKSI_LOG!$J$2:$J$998=H$7)*(TRANSAKSI_LOG!$E$2:$E$998<=$B8)*(TRANSAKSI_LOG!$F$2:$F$998>=$B8),0),0)) & " - " & INDEX(TRANSAKSI_LOG!$H$2:$H$998,MATCH(1,INDEX((TRANSAKSI_LOG!$C$2:$C$998=$C$5)*(TRANSAKSI_LOG!$J$2:$J$998=H$7)*(TRANSAKSI_LOG!$E$2:$E$998<=$B8)*(TRANSAKSI_LOG!$F$2:$F$998>=$B8),0),0)),"")}
B9: 0.33680556 | C9: {=IFERROR(INDEX(TRANSAKSI_LOG!$M$2:$M$998,MATCH(1,INDEX((TRANSAKSI_LOG!$C$2:$C$998=$C$5)*(TRANSAKSI_LOG!$J$2:$J$998=C$7)*(TRANSAKSI_LOG!$E$2:$E$998<=$B9)*(TRANSAKSI_LOG!$F$2:$F$998>=$B9),0),0)) & " - " & INDEX(TRANSAKSI_LOG!$H$2:$H$998,MATCH(1,INDEX((TRANSAKSI_LOG!$C$2:$C$998=$C$5)*(TRANSAKSI_LOG!$J$2:$J$998=C$7)*(TRANSAKSI_LOG!$E$2:$E$998<=$B9)*(TRANSAKSI_LOG!$F$2:$F$998>=$B9),0),0)),"")} | D9: {=IFERROR(INDEX(TRANSAKSI_LOG!$M$2:$M$998,MATCH(1,INDEX((TRANSAKSI_LOG!$C$2:$C$998=$C$5)*(TRANSAKSI_LOG!$J$2:$J$998=D$7)*(TRANSAKSI_LOG!$E$2:$E$998<=$B9)*(TRANSAKSI_LOG!$F$2:$F$998>=$B9),0),0)) & " - " & INDEX(TRANSAKSI_LOG!$H$2:$H$998,MATCH(1,INDEX((TRANSAKSI_LOG!$C$2:$C$998=$C$5)*(TRANSAKSI_LOG!$J$2:$J$998=D$7)*(TRANSAKSI_LOG!$E$2:$E$998<=$B9)*(TRANSAKSI_LOG!$F$2:$F$998>=$B9),0),0)),"")} | E9: {=IFERROR(INDEX(TRANSAKSI_LOG!$M$2:$M$998,MATCH(1,INDEX((TRANSAKSI_LOG!$C$2:$C$998=$C$5)*(TRANSAKSI_LOG!$J$2:$J$998=E$7)*(TRANSAKSI_LOG!$E$2:$E$998<=$B9)*(TRANSAKSI_LOG!$F$2:$F$998>=$B9),0),0)) & " - " & INDEX(TRANSAKSI_LOG!$H$2:$H$998,MATCH(1,INDEX((TRANSAKSI_LOG!$C$2:$C$998=$C$5)*(TRANSAKSI_LOG!$J$2:$J$998=E$7)*(TRANSAKSI_LOG!$E$2:$E$998<=$B9)*(TRANSAKSI_LOG!$F$2:$F$998>=$B9),0),0)),"")} | F9: {=IFERROR(INDEX(TRANSAKSI_LOG!$M$2:$M$998,MATCH(1,INDEX((TRANSAKSI_LOG!$C$2:$C$998=$C$5)*(TRANSAKSI_LOG!$J$2:$J$998=F$7)*(TRANSAKSI_LOG!$E$2:$E$998<=$B9)*(TRANSAKSI_LOG!$F$2:$F$998>=$B9),0),0)) & " - " & INDEX(TRANSAKSI_LOG!$H$2:$H$998,MATCH(1,INDEX((TRANSAKSI_LOG!$C$2:$C$998=$C$5)*(TRANSAKSI_LOG!$J$2:$J$998=F$7)*(TRANSAKSI_LOG!$E$2:$E$998<=$B9)*(TRANSAKSI_LOG!$F$2:$F$998>=$B9),0),0)),"")} | G9: {=IFERROR(INDEX(TRANSAKSI_LOG!$M$2:$M$998,MATCH(1,INDEX((TRANSAKSI_LOG!$C$2:$C$998=$C$5)*(TRANSAKSI_LOG!$J$2:$J$998=G$7)*(TRANSAKSI_LOG!$E$2:$E$998<=$B9)*(TRANSAKSI_LOG!$F$2:$F$998>=$B9),0),0)) & " - " & INDEX(TRANSAKSI_LOG!$H$2:$H$998,MATCH(1,INDEX((TRANSAKSI_LOG!$C$2:$C$998=$C$5)*(TRANSAKSI_LOG!$J$2:$J$998=G$7)*(TRANSAKSI_LOG!$E$2:$E$998<=$B9)*(TRANSAKSI_LOG!$F$2:$F$998>=$B9),0),0)),"")} | H9: {=IFERROR(INDEX(TRANSAKSI_LOG!$M$2:$M$998,MATCH(1,INDEX((TRANSAKSI_LOG!$C$2:$C$998=$C$5)*(TRANSAKSI_LOG!$J$2:$J$998=H$7)*(TRANSAKSI_LOG!$E$2:$E$998<=$B9)*(TRANSAKSI_LOG!$F$2:$F$998>=$B9),0),0)) & " - " & INDEX(TRANSAKSI_LOG!$H$2:$H$998,MATCH(1,INDEX((TRANSAKSI_LOG!$C$2:$C$998=$C$5)*(TRANSAKSI_LOG!$J$2:$J$998=H$7)*(TRANSAKSI_LOG!$E$2:$E$998<=$B9)*(TRANSAKSI_LOG!$F$2:$F$998>=$B9),0),0)),"")}
B10: 0.34027778 | C10: {=IFERROR(INDEX(TRANSAKSI_LOG!$M$2:$M$998,MATCH(1,INDEX((TRANSAKSI_LOG!$C$2:$C$998=$C$5)*(TRANSAKSI_LOG!$J$2:$J$998=C$7)*(TRANSAKSI_LOG!$E$2:$E$998<=$B10)*(TRANSAKSI_LOG!$F$2:$F$998>=$B10),0),0)) & " - " & INDEX(TRANSAKSI_LOG!$H$2:$H$998,MATCH(1,INDEX((TRANSAKSI_LOG!$C$2:$C$998=$C$5)*(TRANSAKSI_LOG!$J$2:$J$998=C$7)*(TRANSAKSI_LOG!$E$2:$E$998<=$B10)*(TRANSAKSI_LOG!$F$2:$F$998>=$B10),0),0)),"")} | D10: {=IFERROR(INDEX(TRANSAKSI_LOG!$M$2:$M$998,MATCH(1,INDEX((TRANSAKSI_LOG!$C$2:$C$998=$C$5)*(TRANSAKSI_LOG!$J$2:$J$998=D$7)*(TRANSAKSI_LOG!$E$2:$E$998<=$B10)*(TRANSAKSI_LOG!$F$2:$F$998>=$B10),0),0)) & " - " & INDEX(TRANSAKSI_LOG!$H$2:$H$998,MATCH(1,INDEX((TRANSAKSI_LOG!$C$2:$C$998=$C$5)*(TRANSAKSI_LOG!$J$2:$J$998=D$7)*(TRANSAKSI_LOG!$E$2:$E$998<=$B10)*(TRANSAKSI_LOG!$F$2:$F$998>=$B10),0),0)),"")} | E10: {=IFERROR(INDEX(TRANSAKSI_LOG!$M$2:$M$998,MATCH(1,INDEX((TRANSAKSI_LOG!$C$2:$C$998=$C$5)*(TRANSAKSI_LOG!$J$2:$J$998=E$7)*(TRANSAKSI_LOG!$E$2:$E$998<=$B10)*(TRANSAKSI_LOG!$F$2:$F$998>=$B10),0),0)) & " - " & INDEX(TRANSAKSI_LOG!$H$2:$H$998,MATCH(1,INDEX((TRANSAKSI_LOG!$C$2:$C$998=$C$5)*(TRANSAKSI_LOG!$J$2:$J$998=E$7)*(TRANSAKSI_LOG!$E$2:$E$998<=$B10)*(TRANSAKSI_LOG!$F$2:$F$998>=$B10),0),0)),"")} | F10: {=IFERROR(INDEX(TRANSAKSI_LOG!$M$2:$M$998,MATCH(1,INDEX((TRANSAKSI_LOG!$C$2:$C$998=$C$5)*(TRANSAKSI_LOG!$J$2:$J$998=F$7)*(TRANSAKSI_LOG!$E$2:$E$998<=$B10)*(TRANSAKSI_LOG!$F$2:$F$998>=$B10),0),0)) & " - " & INDEX(TRANSAKSI_LOG!$H$2:$H$998,MATCH(1,INDEX((TRANSAKSI_LOG!$C$2:$C$998=$C$5)*(TRANSAKSI_LOG!$J$2:$J$998=F$7)*(TRANSAKSI_LOG!$E$2:$E$998<=$B10)*(TRANSAKSI_LOG!$F$2:$F$998>=$B10),0),0)),"")} | G10: {=IFERROR(INDEX(TRANSAKSI_LOG!$M$2:$M$998,MATCH(1,INDEX((TRANSAKSI_LOG!$C$2:$C$998=$C$5)*(TRANSAKSI_LOG!$J$2:$J$998=G$7)*(TRANSAKSI_LOG!$E$2:$E$998<=$B10)*(TRANSAKSI_LOG!$F$2:$F$998>=$B10),0),0)) & " - " & INDEX(TRANSAKSI_LOG!$H$2:$H$998,MATCH(1,INDEX((TRANSAKSI_LOG!$C$2:$C$998=$C$5)*(TRANSAKSI_LOG!$J$2:$J$998=G$7)*(TRANSAKSI_LOG!$E$2:$E$998<=$B10)*(TRANSAKSI_LOG!$F$2:$F$998>=$B10),0),0)),"")} | H10: {=IFERROR(INDEX(TRANSAKSI_LOG!$M$2:$M$998,MATCH(1,INDEX((TRANSAKSI_LOG!$C$2:$C$998=$C$5)*(TRANSAKSI_LOG!$J$2:$J$998=H$7)*(TRANSAKSI_LOG!$E$2:$E$998<=$B10)*(TRANSAKSI_LOG!$F$2:$F$998>=$B10),0),0)) & " - " & INDEX(TRANSAKSI_LOG!$H$2:$H$998,MATCH(1,INDEX((TRANSAKSI_LOG!$C$2:$C$998=$C$5)*(TRANSAKSI_LOG!$J$2:$J$998=H$7)*(TRANSAKSI_LOG!$E$2:$E$998<=$B10)*(TRANSAKSI_LOG!$F$2:$F$998>=$B10),0),0)),"")}
B11: 0.34375 | C11: {=IFERROR(INDEX(TRANSAKSI_LOG!$M$2:$M$998,MATCH(1,INDEX((TRANSAKSI_LOG!$C$2:$C$998=$C$5)*(TRANSAKSI_LOG!$J$2:$J$998=C$7)*(TRANSAKSI_LOG!$E$2:$E$998<=$B11)*(TRANSAKSI_LOG!$F$2:$F$998>=$B11),0),0)) & " - " & INDEX(TRANSAKSI_LOG!$H$2:$H$998,MATCH(1,INDEX((TRANSAKSI_LOG!$C$2:$C$998=$C$5)*(TRANSAKSI_LOG!$J$2:$J$998=C$7)*(TRANSAKSI_LOG!$E$2:$E$998<=$B11)*(TRANSAKSI_LOG!$F$2:$F$998>=$B11),0),0)),"")} | D11: {=IFERROR(INDEX(TRANSAKSI_LOG!$M$2:$M$998,MATCH(1,INDEX((TRANSAKSI_LOG!$C$2:$C$998=$C$5)*(TRANSAKSI_LOG!$J$2:$J$998=D$7)*(TRANSAKSI_LOG!$E$2:$E$998<=$B11)*(TRANSAKSI_LOG!$F$2:$F$998>=$B11),0),0)) & " - " & INDEX(TRANSAKSI_LOG!$H$2:$H$998,MATCH(1,INDEX((TRANSAKSI_LOG!$C$2:$C$998=$C$5)*(TRANSAKSI_LOG!$J$2:$J$998=D$7)*(TRANSAKSI_LOG!$E$2:$E$998<=$B11)*(TRANSAKSI_LOG!$F$2:$F$998>=$B11),0),0)),"")} | E11: {=IFERROR(INDEX(TRANSAKSI_LOG!$M$2:$M$998,MATCH(1,INDEX((TRANSAKSI_LOG!$C$2:$C$998=$C$5)*(TRANSAKSI_LOG!$J$2:$J$998=E$7)*(TRANSAKSI_LOG!$E$2:$E$998<=$B11)*(TRANSAKSI_LOG!$F$2:$F$998>=$B11),0),0)) & " - " & INDEX(TRANSAKSI_LOG!$H$2:$H$998,MATCH(1,INDEX((TRANSAKSI_LOG!$C$2:$C$998=$C$5)*(TRANSAKSI_LOG!$J$2:$J$998=E$7)*(TRANSAKSI_LOG!$E$2:$E$998<=$B11)*(TRANSAKSI_LOG!$F$2:$F$998>=$B11),0),0)),"")} | F11: {=IFERROR(INDEX(TRANSAKSI_LOG!$M$2:$M$998,MATCH(1,INDEX((TRANSAKSI_LOG!$C$2:$C$998=$C$5)*(TRANSAKSI_LOG!$J$2:$J$998=F$7)*(TRANSAKSI_LOG!$E$2:$E$998<=$B11)*(TRANSAKSI_LOG!$F$2:$F$998>=$B11),0),0)) & " - " & INDEX(TRANSAKSI_LOG!$H$2:$H$998,MATCH(1,INDEX((TRANSAKSI_LOG!$C$2:$C$998=$C$5)*(TRANSAKSI_LOG!$J$2:$J$998=F$7)*(TRANSAKSI_LOG!$E$2:$E$998<=$B11)*(TRANSAKSI_LOG!$F$2:$F$998>=$B11),0),0)),"")} | G11: {=IFERROR(INDEX(TRANSAKSI_LOG!$M$2:$M$998,MATCH(1,INDEX((TRANSAKSI_LOG!$C$2:$C$998=$C$5)*(TRANSAKSI_LOG!$J$2:$J$998=G$7)*(TRANSAKSI_LOG!$E$2:$E$998<=$B11)*(TRANSAKSI_LOG!$F$2:$F$998>=$B11),0),0)) & " - " & INDEX(TRANSAKSI_LOG!$H$2:$H$998,MATCH(1,INDEX((TRANSAKSI_LOG!$C$2:$C$998=$C$5)*(TRANSAKSI_LOG!$J$2:$J$998=G$7)*(TRANSAKSI_LOG!$E$2:$E$998<=$B11)*(TRANSAKSI_LOG!$F$2:$F$998>=$B11),0),0)),"")} | H11: {=IFERROR(INDEX(TRANSAKSI_LOG!$M$2:$M$998,MATCH(1,INDEX((TRANSAKSI_LOG!$C$2:$C$998=$C$5)*(TRANSAKSI_LOG!$J$2:$J$998=H$7)*(TRANSAKSI_LOG!$E$2:$E$998<=$B11)*(TRANSAKSI_LOG!$F$2:$F$998>=$B11),0),0)) & " - " & INDEX(TRANSAKSI_LOG!$H$2:$H$998,MATCH(1,INDEX((TRANSAKSI_LOG!$C$2:$C$998=$C$5)*(TRANSAKSI_LOG!$J$2:$J$998=H$7)*(TRANSAKSI_LOG!$E$2:$E$998<=$B11)*(TRANSAKSI_LOG!$F$2:$F$998>=$B11),0),0)),"")}
B12: 0.34722222 | C12: {=IFERROR(INDEX(TRANSAKSI_LOG!$M$2:$M$998,MATCH(1,INDEX((TRANSAKSI_LOG!$C$2:$C$998=$C$5)*(TRANSAKSI_LOG!$J$2:$J$998=C$7)*(TRANSAKSI_LOG!$E$2:$E$998<=$B12)*(TRANSAKSI_LOG!$F$2:$F$998>=$B12),0),0)) & " - " & INDEX(TRANSAKSI_LOG!$H$2:$H$998,MATCH(1,INDEX((TRANSAKSI_LOG!$C$2:$C$998=$C$5)*(TRANSAKSI_LOG!$J$2:$J$998=C$7)*(TRANSAKSI_LOG!$E$2:$E$998<=$B12)*(TRANSAKSI_LOG!$F$2:$F$998>=$B12),0),0)),"")} | D12: {=IFERROR(INDEX(TRANSAKSI_LOG!$M$2:$M$998,MATCH(1,INDEX((TRANSAKSI_LOG!$C$2:$C$998=$C$5)*(TRANSAKSI_LOG!$J$2:$J$998=D$7)*(TRANSAKSI_LOG!$E$2:$E$998<=$B12)*(TRANSAKSI_LOG!$F$2:$F$998>=$B12),0),0)) & " - " & INDEX(TRANSAKSI_LOG!$H$2:$H$998,MATCH(1,INDEX((TRANSAKSI_LOG!$C$2:$C$998=$C$5)*(TRANSAKSI_LOG!$J$2:$J$998=D$7)*(TRANSAKSI_LOG!$E$2:$E$998<=$B12)*(TRANSAKSI_LOG!$F$2:$F$998>=$B12),0),0)),"")} | E12: {=IFERROR(INDEX(TRANSAKSI_LOG!$M$2:$M$998,MATCH(1,INDEX((TRANSAKSI_LOG!$C$2:$C$998=$C$5)*(TRANSAKSI_LOG!$J$2:$J$998=E$7)*(TRANSAKSI_LOG!$E$2:$E$998<=$B12)*(TRANSAKSI_LOG!$F$2:$F$998>=$B12),0),0)) & " - " & INDEX(TRANSAKSI_LOG!$H$2:$H$998,MATCH(1,INDEX((TRANSAKSI_LOG!$C$2:$C$998=$C$5)*(TRANSAKSI_LOG!$J$2:$J$998=E$7)*(TRANSAKSI_LOG!$E$2:$E$998<=$B12)*(TRANSAKSI_LOG!$F$2:$F$998>=$B12),0),0)),"")} | F12: {=IFERROR(INDEX(TRANSAKSI_LOG!$M$2:$M$998,MATCH(1,INDEX((TRANSAKSI_LOG!$C$2:$C$998=$C$5)*(TRANSAKSI_LOG!$J$2:$J$998=F$7)*(TRANSAKSI_LOG!$E$2:$E$998<=$B12)*(TRANSAKSI_LOG!$F$2:$F$998>=$B12),0),0)) & " - " & INDEX(TRANSAKSI_LOG!$H$2:$H$998,MATCH(1,INDEX((TRANSAKSI_LOG!$C$2:$C$998=$C$5)*(TRANSAKSI_LOG!$J$2:$J$998=F$7)*(TRANSAKSI_LOG!$E$2:$E$998<=$B12)*(TRANSAKSI_LOG!$F$2:$F$998>=$B12),0),0)),"")} | G12: {=IFERROR(INDEX(TRANSAKSI_LOG!$M$2:$M$998,MATCH(1,INDEX((TRANSAKSI_LOG!$C$2:$C$998=$C$5)*(TRANSAKSI_LOG!$J$2:$J$998=G$7)*(TRANSAKSI_LOG!$E$2:$E$998<=$B12)*(TRANSAKSI_LOG!$F$2:$F$998>=$B12),0),0)) & " - " & INDEX(TRANSAKSI_LOG!$H$2:$H$998,MATCH(1,INDEX((TRANSAKSI_LOG!$C$2:$C$998=$C$5)*(TRANSAKSI_LOG!$J$2:$J$998=G$7)*(TRANSAKSI_LOG!$E$2:$E$998<=$B12)*(TRANSAKSI_LOG!$F$2:$F$998>=$B12),0),0)),"")} | H12: {=IFERROR(INDEX(TRANSAKSI_LOG!$M$2:$M$998,MATCH(1,INDEX((TRANSAKSI_LOG!$C$2:$C$998=$C$5)*(TRANSAKSI_LOG!$J$2:$J$998=H$7)*(TRANSAKSI_LOG!$E$2:$E$998<=$B12)*(TRANSAKSI_LOG!$F$2:$F$998>=$B12),0),0)) & " - " & INDEX(TRANSAKSI_LOG!$H$2:$H$998,MATCH(1,INDEX((TRANSAKSI_LOG!$C$2:$C$998=$C$5)*(TRANSAKSI_LOG!$J$2:$J$998=H$7)*(TRANSAKSI_LOG!$E$2:$E$998<=$B12)*(TRANSAKSI_LOG!$F$2:$F$998>=$B12),0),0)),"")}
B13: 0.35069444 | C13: {=IFERROR(INDEX(TRANSAKSI_LOG!$M$2:$M$998,MATCH(1,INDEX((TRANSAKSI_LOG!$C$2:$C$998=$C$5)*(TRANSAKSI_LOG!$J$2:$J$998=C$7)*(TRANSAKSI_LOG!$E$2:$E$998<=$B13)*(TRANSAKSI_LOG!$F$2:$F$998>=$B13),0),0)) & " - " & INDEX(TRANSAKSI_LOG!$H$2:$H$998,MATCH(1,INDEX((TRANSAKSI_LOG!$C$2:$C$998=$C$5)*(TRANSAKSI_LOG!$J$2:$J$998=C$7)*(TRANSAKSI_LOG!$E$2:$E$998<=$B13)*(TRANSAKSI_LOG!$F$2:$F$998>=$B13),0),0)),"")} | D13: {=IFERROR(INDEX(TRANSAKSI_LOG!$M$2:$M$998,MATCH(1,INDEX((TRANSAKSI_LOG!$C$2:$C$998=$C$5)*(TRANSAKSI_LOG!$J$2:$J$998=D$7)*(TRANSAKSI_LOG!$E$2:$E$998<=$B13)*(TRANSAKSI_LOG!$F$2:$F$998>=$B13),0),0)) & " - " & INDEX(TRANSAKSI_LOG!$H$2:$H$998,MATCH(1,INDEX((TRANSAKSI_LOG!$C$2:$C$998=$C$5)*(TRANSAKSI_LOG!$J$2:$J$998=D$7)*(TRANSAKSI_LOG!$E$2:$E$998<=$B13)*(TRANSAKSI_LOG!$F$2:$F$998>=$B13),0),0)),"")} | E13: {=IFERROR(INDEX(TRANSAKSI_LOG!$M$2:$M$998,MATCH(1,INDEX((TRANSAKSI_LOG!$C$2:$C$998=$C$5)*(TRANSAKSI_LOG!$J$2:$J$998=E$7)*(TRANSAKSI_LOG!$E$2:$E$998<=$B13)*(TRANSAKSI_LOG!$F$2:$F$998>=$B13),0),0)) & " - " & INDEX(TRANSAKSI_LOG!$H$2:$H$998,MATCH(1,INDEX((TRANSAKSI_LOG!$C$2:$C$998=$C$5)*(TRANSAKSI_LOG!$J$2:$J$998=E$7)*(TRANSAKSI_LOG!$E$2:$E$998<=$B13)*(TRANSAKSI_LOG!$F$2:$F$998>=$B13),0),0)),"")} | F13: {=IFERROR(INDEX(TRANSAKSI_LOG!$M$2:$M$998,MATCH(1,INDEX((TRANSAKSI_LOG!$C$2:$C$998=$C$5)*(TRANSAKSI_LOG!$J$2:$J$998=F$7)*(TRANSAKSI_LOG!$E$2:$E$998<=$B13)*(TRANSAKSI_LOG!$F$2:$F$998>=$B13),0),0)) & " - " & INDEX(TRANSAKSI_LOG!$H$2:$H$998,MATCH(1,INDEX((TRANSAKSI_LOG!$C$2:$C$998=$C$5)*(TRANSAKSI_LOG!$J$2:$J$998=F$7)*(TRANSAKSI_LOG!$E$2:$E$998<=$B13)*(TRANSAKSI_LOG!$F$2:$F$998>=$B13),0),0)),"")} | G13: {=IFERROR(INDEX(TRANSAKSI_LOG!$M$2:$M$998,MATCH(1,INDEX((TRANSAKSI_LOG!$C$2:$C$998=$C$5)*(TRANSAKSI_LOG!$J$2:$J$998=G$7)*(TRANSAKSI_LOG!$E$2:$E$998<=$B13)*(TRANSAKSI_LOG!$F$2:$F$998>=$B13),0),0)) & " - " & INDEX(TRANSAKSI_LOG!$H$2:$H$998,MATCH(1,INDEX((TRANSAKSI_LOG!$C$2:$C$998=$C$5)*(TRANSAKSI_LOG!$J$2:$J$998=G$7)*(TRANSAKSI_LOG!$E$2:$E$998<=$B13)*(TRANSAKSI_LOG!$F$2:$F$998>=$B13),0),0)),"")} | H13: {=IFERROR(INDEX(TRANSAKSI_LOG!$M$2:$M$998,MATCH(1,INDEX((TRANSAKSI_LOG!$C$2:$C$998=$C$5)*(TRANSAKSI_LOG!$J$2:$J$998=H$7)*(TRANSAKSI_LOG!$E$2:$E$998<=$B13)*(TRANSAKSI_LOG!$F$2:$F$998>=$B13),0),0)) & " - " & INDEX(TRANSAKSI_LOG!$H$2:$H$998,MATCH(1,INDEX((TRANSAKSI_LOG!$C$2:$C$998=$C$5)*(TRANSAKSI_LOG!$J$2:$J$998=H$7)*(TRANSAKSI_LOG!$E$2:$E$998<=$B13)*(TRANSAKSI_LOG!$F$2:$F$998>=$B13),0),0)),"")}
B14: 0.35416667 | C14: {=IFERROR(INDEX(TRANSAKSI_LOG!$M$2:$M$998,MATCH(1,INDEX((TRANSAKSI_LOG!$C$2:$C$998=$C$5)*(TRANSAKSI_LOG!$J$2:$J$998=C$7)*(TRANSAKSI_LOG!$E$2:$E$998<=$B14)*(TRANSAKSI_LOG!$F$2:$F$998>=$B14),0),0)) & " - " & INDEX(TRANSAKSI_LOG!$H$2:$H$998,MATCH(1,INDEX((TRANSAKSI_LOG!$C$2:$C$998=$C$5)*(TRANSAKSI_LOG!$J$2:$J$998=C$7)*(TRANSAKSI_LOG!$E$2:$E$998<=$B14)*(TRANSAKSI_LOG!$F$2:$F$998>=$B14),0),0)),"")} | D14: {=IFERROR(INDEX(TRANSAKSI_LOG!$M$2:$M$998,MATCH(1,INDEX((TRANSAKSI_LOG!$C$2:$C$998=$C$5)*(TRANSAKSI_LOG!$J$2:$J$998=D$7)*(TRANSAKSI_LOG!$E$2:$E$998<=$B14)*(TRANSAKSI_LOG!$F$2:$F$998>=$B14),0),0)) & " - " & INDEX(TRANSAKSI_LOG!$H$2:$H$998,MATCH(1,INDEX((TRANSAKSI_LOG!$C$2:$C$998=$C$5)*(TRANSAKSI_LOG!$J$2:$J$998=D$7)*(TRANSAKSI_LOG!$E$2:$E$998<=$B14)*(TRANSAKSI_LOG!$F$2:$F$998>=$B14),0),0)),"")} | E14: {=IFERROR(INDEX(TRANSAKSI_LOG!$M$2:$M$998,MATCH(1,INDEX((TRANSAKSI_LOG!$C$2:$C$998=$C$5)*(TRANSAKSI_LOG!$J$2:$J$998=E$7)*(TRANSAKSI_LOG!$E$2:$E$998<=$B14)*(TRANSAKSI_LOG!$F$2:$F$998>=$B14),0),0)) & " - " & INDEX(TRANSAKSI_LOG!$H$2:$H$998,MATCH(1,INDEX((TRANSAKSI_LOG!$C$2:$C$998=$C$5)*(TRANSAKSI_LOG!$J$2:$J$998=E$7)*(TRANSAKSI_LOG!$E$2:$E$998<=$B14)*(TRANSAKSI_LOG!$F$2:$F$998>=$B14),0),0)),"")} | F14: {=IFERROR(INDEX(TRANSAKSI_LOG!$M$2:$M$998,MATCH(1,INDEX((TRANSAKSI_LOG!$C$2:$C$998=$C$5)*(TRANSAKSI_LOG!$J$2:$J$998=F$7)*(TRANSAKSI_LOG!$E$2:$E$998<=$B14)*(TRANSAKSI_LOG!$F$2:$F$998>=$B14),0),0)) & " - " & INDEX(TRANSAKSI_LOG!$H$2:$H$998,MATCH(1,INDEX((TRANSAKSI_LOG!$C$2:$C$998=$C$5)*(TRANSAKSI_LOG!$J$2:$J$998=F$7)*(TRANSAKSI_LOG!$E$2:$E$998<=$B14)*(TRANSAKSI_LOG!$F$2:$F$998>=$B14),0),0)),"")} | G14: {=IFERROR(INDEX(TRANSAKSI_LOG!$M$2:$M$998,MATCH(1,INDEX((TRANSAKSI_LOG!$C$2:$C$998=$C$5)*(TRANSAKSI_LOG!$J$2:$J$998=G$7)*(TRANSAKSI_LOG!$E$2:$E$998<=$B14)*(TRANSAKSI_LOG!$F$2:$F$998>=$B14),0),0)) & " - " & INDEX(TRANSAKSI_LOG!$H$2:$H$998,MATCH(1,INDEX((TRANSAKSI_LOG!$C$2:$C$998=$C$5)*(TRANSAKSI_LOG!$J$2:$J$998=G$7)*(TRANSAKSI_LOG!$E$2:$E$998<=$B14)*(TRANSAKSI_LOG!$F$2:$F$998>=$B14),0),0)),"")} | H14: {=IFERROR(INDEX(TRANSAKSI_LOG!$M$2:$M$998,MATCH(1,INDEX((TRANSAKSI_LOG!$C$2:$C$998=$C$5)*(TRANSAKSI_LOG!$J$2:$J$998=H$7)*(TRANSAKSI_LOG!$E$2:$E$998<=$B14)*(TRANSAKSI_LOG!$F$2:$F$998>=$B14),0),0)) & " - " & INDEX(TRANSAKSI_LOG!$H$2:$H$998,MATCH(1,INDEX((TRANSAKSI_LOG!$C$2:$C$998=$C$5)*(TRANSAKSI_LOG!$J$2:$J$998=H$7)*(TRANSAKSI_LOG!$E$2:$E$998<=$B14)*(TRANSAKSI_LOG!$F$2:$F$998>=$B14),0),0)),"")}
B15: 0.35763889 | C15: {=IFERROR(INDEX(TRANSAKSI_LOG!$M$2:$M$998,MATCH(1,INDEX((TRANSAKSI_LOG!$C$2:$C$998=$C$5)*(TRANSAKSI_LOG!$J$2:$J$998=C$7)*(TRANSAKSI_LOG!$E$2:$E$998<=$B15)*(TRANSAKSI_LOG!$F$2:$F$998>=$B15),0),0)) & " - " & INDEX(TRANSAKSI_LOG!$H$2:$H$998,MATCH(1,INDEX((TRANSAKSI_LOG!$C$2:$C$998=$C$5)*(TRANSAKSI_LOG!$J$2:$J$998=C$7)*(TRANSAKSI_LOG!$E$2:$E$998<=$B15)*(TRANSAKSI_LOG!$F$2:$F$998>=$B15),0),0)),"")} | D15: {=IFERROR(INDEX(TRANSAKSI_LOG!$M$2:$M$998,MATCH(1,INDEX((TRANSAKSI_LOG!$C$2:$C$998=$C$5)*(TRANSAKSI_LOG!$J$2:$J$998=D$7)*(TRANSAKSI_LOG!$E$2:$E$998<=$B15)*(TRANSAKSI_LOG!$F$2:$F$998>=$B15),0),0)) & " - " & INDEX(TRANSAKSI_LOG!$H$2:$H$998,MATCH(1,INDEX((TRANSAKSI_LOG!$C$2:$C$998=$C$5)*(TRANSAKSI_LOG!$J$2:$J$998=D$7)*(TRANSAKSI_LOG!$E$2:$E$998<=$B15)*(TRANSAKSI_LOG!$F$2:$F$998>=$B15),0),0)),"")} | E15: {=IFERROR(INDEX(TRANSAKSI_LOG!$M$2:$M$998,MATCH(1,INDEX((TRANSAKSI_LOG!$C$2:$C$998=$C$5)*(TRANSAKSI_LOG!$J$2:$J$998=E$7)*(TRANSAKSI_LOG!$E$2:$E$998<=$B15)*(TRANSAKSI_LOG!$F$2:$F$998>=$B15),0),0)) & " - " & INDEX(TRANSAKSI_LOG!$H$2:$H$998,MATCH(1,INDEX((TRANSAKSI_LOG!$C$2:$C$998=$C$5)*(TRANSAKSI_LOG!$J$2:$J$998=E$7)*(TRANSAKSI_LOG!$E$2:$E$998<=$B15)*(TRANSAKSI_LOG!$F$2:$F$998>=$B15),0),0)),"")} | F15: {=IFERROR(INDEX(TRANSAKSI_LOG!$M$2:$M$998,MATCH(1,INDEX((TRANSAKSI_LOG!$C$2:$C$998=$C$5)*(TRANSAKSI_LOG!$J$2:$J$998=F$7)*(TRANSAKSI_LOG!$E$2:$E$998<=$B15)*(TRANSAKSI_LOG!$F$2:$F$998>=$B15),0),0)) & " - " & INDEX(TRANSAKSI_LOG!$H$2:$H$998,MATCH(1,INDEX((TRANSAKSI_LOG!$C$2:$C$998=$C$5)*(TRANSAKSI_LOG!$J$2:$J$998=F$7)*(TRANSAKSI_LOG!$E$2:$E$998<=$B15)*(TRANSAKSI_LOG!$F$2:$F$998>=$B15),0),0)),"")} | G15: {=IFERROR(INDEX(TRANSAKSI_LOG!$M$2:$M$998,MATCH(1,INDEX((TRANSAKSI_LOG!$C$2:$C$998=$C$5)*(TRANSAKSI_LOG!$J$2:$J$998=G$7)*(TRANSAKSI_LOG!$E$2:$E$998<=$B15)*(TRANSAKSI_LOG!$F$2:$F$998>=$B15),0),0)) & " - " & INDEX(TRANSAKSI_LOG!$H$2:$H$998,MATCH(1,INDEX((TRANSAKSI_LOG!$C$2:$C$998=$C$5)*(TRANSAKSI_LOG!$J$2:$J$998=G$7)*(TRANSAKSI_LOG!$E$2:$E$998<=$B15)*(TRANSAKSI_LOG!$F$2:$F$998>=$B15),0),0)),"")} | H15: {=IFERROR(INDEX(TRANSAKSI_LOG!$M$2:$M$998,MATCH(1,INDEX((TRANSAKSI_LOG!$C$2:$C$998=$C$5)*(TRANSAKSI_LOG!$J$2:$J$998=H$7)*(TRANSAKSI_LOG!$E$2:$E$998<=$B15)*(TRANSAKSI_LOG!$F$2:$F$998>=$B15),0),0)) & " - " & INDEX(TRANSAKSI_LOG!$H$2:$H$998,MATCH(1,INDEX((TRANSAKSI_LOG!$C$2:$C$998=$C$5)*(TRANSAKSI_LOG!$J$2:$J$998=H$7)*(TRANSAKSI_LOG!$E$2:$E$998<=$B15)*(TRANSAKSI_LOG!$F$2:$F$998>=$B15),0),0)),"")}
B16: 0.36111111 | C16: {=IFERROR(INDEX(TRANSAKSI_LOG!$M$2:$M$998,MATCH(1,INDEX((TRANSAKSI_LOG!$C$2:$C$998=$C$5)*(TRANSAKSI_LOG!$J$2:$J$998=C$7)*(TRANSAKSI_LOG!$E$2:$E$998<=$B16)*(TRANSAKSI_LOG!$F$2:$F$998>=$B16),0),0)) & " - " & INDEX(TRANSAKSI_LOG!$H$2:$H$998,MATCH(1,INDEX((TRANSAKSI_LOG!$C$2:$C$998=$C$5)*(TRANSAKSI_LOG!$J$2:$J$998=C$7)*(TRANSAKSI_LOG!$E$2:$E$998<=$B16)*(TRANSAKSI_LOG!$F$2:$F$998>=$B16),0),0)),"")} | D16: {=IFERROR(INDEX(TRANSAKSI_LOG!$M$2:$M$998,MATCH(1,INDEX((TRANSAKSI_LOG!$C$2:$C$998=$C$5)*(TRANSAKSI_LOG!$J$2:$J$998=D$7)*(TRANSAKSI_LOG!$E$2:$E$998<=$B16)*(TRANSAKSI_LOG!$F$2:$F$998>=$B16),0),0)) & " - " & INDEX(TRANSAKSI_LOG!$H$2:$H$998,MATCH(1,INDEX((TRANSAKSI_LOG!$C$2:$C$998=$C$5)*(TRANSAKSI_LOG!$J$2:$J$998=D$7)*(TRANSAKSI_LOG!$E$2:$E$998<=$B16)*(TRANSAKSI_LOG!$F$2:$F$998>=$B16),0),0)),"")} | E16: {=IFERROR(INDEX(TRANSAKSI_LOG!$M$2:$M$998,MATCH(1,INDEX((TRANSAKSI_LOG!$C$2:$C$998=$C$5)*(TRANSAKSI_LOG!$J$2:$J$998=E$7)*(TRANSAKSI_LOG!$E$2:$E$998<=$B16)*(TRANSAKSI_LOG!$F$2:$F$998>=$B16),0),0)) & " - " & INDEX(TRANSAKSI_LOG!$H$2:$H$998,MATCH(1,INDEX((TRANSAKSI_LOG!$C$2:$C$998=$C$5)*(TRANSAKSI_LOG!$J$2:$J$998=E$7)*(TRANSAKSI_LOG!$E$2:$E$998<=$B16)*(TRANSAKSI_LOG!$F$2:$F$998>=$B16),0),0)),"")} | F16: {=IFERROR(INDEX(TRANSAKSI_LOG!$M$2:$M$998,MATCH(1,INDEX((TRANSAKSI_LOG!$C$2:$C$998=$C$5)*(TRANSAKSI_LOG!$J$2:$J$998=F$7)*(TRANSAKSI_LOG!$E$2:$E$998<=$B16)*(TRANSAKSI_LOG!$F$2:$F$998>=$B16),0),0)) & " - " & INDEX(TRANSAKSI_LOG!$H$2:$H$998,MATCH(1,INDEX((TRANSAKSI_LOG!$C$2:$C$998=$C$5)*(TRANSAKSI_LOG!$J$2:$J$998=F$7)*(TRANSAKSI_LOG!$E$2:$E$998<=$B16)*(TRANSAKSI_LOG!$F$2:$F$998>=$B16),0),0)),"")} | G16: {=IFERROR(INDEX(TRANSAKSI_LOG!$M$2:$M$998,MATCH(1,INDEX((TRANSAKSI_LOG!$C$2:$C$998=$C$5)*(TRANSAKSI_LOG!$J$2:$J$998=G$7)*(TRANSAKSI_LOG!$E$2:$E$998<=$B16)*(TRANSAKSI_LOG!$F$2:$F$998>=$B16),0),0)) & " - " & INDEX(TRANSAKSI_LOG!$H$2:$H$998,MATCH(1,INDEX((TRANSAKSI_LOG!$C$2:$C$998=$C$5)*(TRANSAKSI_LOG!$J$2:$J$998=G$7)*(TRANSAKSI_LOG!$E$2:$E$998<=$B16)*(TRANSAKSI_LOG!$F$2:$F$998>=$B16),0),0)),"")} | H16: {=IFERROR(INDEX(TRANSAKSI_LOG!$M$2:$M$998,MATCH(1,INDEX((TRANSAKSI_LOG!$C$2:$C$998=$C$5)*(TRANSAKSI_LOG!$J$2:$J$998=H$7)*(TRANSAKSI_LOG!$E$2:$E$998<=$B16)*(TRANSAKSI_LOG!$F$2:$F$998>=$B16),0),0)) & " - " & INDEX(TRANSAKSI_LOG!$H$2:$H$998,MATCH(1,INDEX((TRANSAKSI_LOG!$C$2:$C$998=$C$5)*(TRANSAKSI_LOG!$J$2:$J$998=H$7)*(TRANSAKSI_LOG!$E$2:$E$998<=$B16)*(TRANSAKSI_LOG!$F$2:$F$998>=$B16),0),0)),"")}
B17: 0.36458333 | C17: {=IFERROR(INDEX(TRANSAKSI_LOG!$M$2:$M$998,MATCH(1,INDEX((TRANSAKSI_LOG!$C$2:$C$998=$C$5)*(TRANSAKSI_LOG!$J$2:$J$998=C$7)*(TRANSAKSI_LOG!$E$2:$E$998<=$B17)*(TRANSAKSI_LOG!$F$2:$F$998>=$B17),0),0)) & " - " & INDEX(TRANSAKSI_LOG!$H$2:$H$998,MATCH(1,INDEX((TRANSAKSI_LOG!$C$2:$C$998=$C$5)*(TRANSAKSI_LOG!$J$2:$J$998=C$7)*(TRANSAKSI_LOG!$E$2:$E$998<=$B17)*(TRANSAKSI_LOG!$F$2:$F$998>=$B17),0),0)),"")} | D17: {=IFERROR(INDEX(TRANSAKSI_LOG!$M$2:$M$998,MATCH(1,INDEX((TRANSAKSI_LOG!$C$2:$C$998=$C$5)*(TRANSAKSI_LOG!$J$2:$J$998=D$7)*(TRANSAKSI_LOG!$E$2:$E$998<=$B17)*(TRANSAKSI_LOG!$F$2:$F$998>=$B17),0),0)) & " - " & INDEX(TRANSAKSI_LOG!$H$2:$H$998,MATCH(1,INDEX((TRANSAKSI_LOG!$C$2:$C$998=$C$5)*(TRANSAKSI_LOG!$J$2:$J$998=D$7)*(TRANSAKSI_LOG!$E$2:$E$998<=$B17)*(TRANSAKSI_LOG!$F$2:$F$998>=$B17),0),0)),"")} | E17: {=IFERROR(INDEX(TRANSAKSI_LOG!$M$2:$M$998,MATCH(1,INDEX((TRANSAKSI_LOG!$C$2:$C$998=$C$5)*(TRANSAKSI_LOG!$J$2:$J$998=E$7)*(TRANSAKSI_LOG!$E$2:$E$998<=$B17)*(TRANSAKSI_LOG!$F$2:$F$998>=$B17),0),0)) & " - " & INDEX(TRANSAKSI_LOG!$H$2:$H$998,MATCH(1,INDEX((TRANSAKSI_LOG!$C$2:$C$998=$C$5)*(TRANSAKSI_LOG!$J$2:$J$998=E$7)*(TRANSAKSI_LOG!$E$2:$E$998<=$B17)*(TRANSAKSI_LOG!$F$2:$F$998>=$B17),0),0)),"")} | F17: {=IFERROR(INDEX(TRANSAKSI_LOG!$M$2:$M$998,MATCH(1,INDEX((TRANSAKSI_LOG!$C$2:$C$998=$C$5)*(TRANSAKSI_LOG!$J$2:$J$998=F$7)*(TRANSAKSI_LOG!$E$2:$E$998<=$B17)*(TRANSAKSI_LOG!$F$2:$F$998>=$B17),0),0)) & " - " & INDEX(TRANSAKSI_LOG!$H$2:$H$998,MATCH(1,INDEX((TRANSAKSI_LOG!$C$2:$C$998=$C$5)*(TRANSAKSI_LOG!$J$2:$J$998=F$7)*(TRANSAKSI_LOG!$E$2:$E$998<=$B17)*(TRANSAKSI_LOG!$F$2:$F$998>=$B17),0),0)),"")} | G17: {=IFERROR(INDEX(TRANSAKSI_LOG!$M$2:$M$998,MATCH(1,INDEX((TRANSAKSI_LOG!$C$2:$C$998=$C$5)*(TRANSAKSI_LOG!$J$2:$J$998=G$7)*(TRANSAKSI_LOG!$E$2:$E$998<=$B17)*(TRANSAKSI_LOG!$F$2:$F$998>=$B17),0),0)) & " - " & INDEX(TRANSAKSI_LOG!$H$2:$H$998,MATCH(1,INDEX((TRANSAKSI_LOG!$C$2:$C$998=$C$5)*(TRANSAKSI_LOG!$J$2:$J$998=G$7)*(TRANSAKSI_LOG!$E$2:$E$998<=$B17)*(TRANSAKSI_LOG!$F$2:$F$998>=$B17),0),0)),"")} | H17: {=IFERROR(INDEX(TRANSAKSI_LOG!$M$2:$M$998,MATCH(1,INDEX((TRANSAKSI_LOG!$C$2:$C$998=$C$5)*(TRANSAKSI_LOG!$J$2:$J$998=H$7)*(TRANSAKSI_LOG!$E$2:$E$998<=$B17)*(TRANSAKSI_LOG!$F$2:$F$998>=$B17),0),0)) & " - " & INDEX(TRANSAKSI_LOG!$H$2:$H$998,MATCH(1,INDEX((TRANSAKSI_LOG!$C$2:$C$998=$C$5)*(TRANSAKSI_LOG!$J$2:$J$998=H$7)*(TRANSAKSI_LOG!$E$2:$E$998<=$B17)*(TRANSAKSI_LOG!$F$2:$F$998>=$B17),0),0)),"")}
B18: 0.36805556 | C18: {=IFERROR(INDEX(TRANSAKSI_LOG!$M$2:$M$998,MATCH(1,INDEX((TRANSAKSI_LOG!$C$2:$C$998=$C$5)*(TRANSAKSI_LOG!$J$2:$J$998=C$7)*(TRANSAKSI_LOG!$E$2:$E$998<=$B18)*(TRANSAKSI_LOG!$F$2:$F$998>=$B18),0),0)) & " - " & INDEX(TRANSAKSI_LOG!$H$2:$H$998,MATCH(1,INDEX((TRANSAKSI_LOG!$C$2:$C$998=$C$5)*(TRANSAKSI_LOG!$J$2:$J$998=C$7)*(TRANSAKSI_LOG!$E$2:$E$998<=$B18)*(TRANSAKSI_LOG!$F$2:$F$998>=$B18),0),0)),"")} | D18: {=IFERROR(INDEX(TRANSAKSI_LOG!$M$2:$M$998,MATCH(1,INDEX((TRANSAKSI_LOG!$C$2:$C$998=$C$5)*(TRANSAKSI_LOG!$J$2:$J$998=D$7)*(TRANSAKSI_LOG!$E$2:$E$998<=$B18)*(TRANSAKSI_LOG!$F$2:$F$998>=$B18),0),0)) & " - " & INDEX(TRANSAKSI_LOG!$H$2:$H$998,MATCH(1,INDEX((TRANSAKSI_LOG!$C$2:$C$998=$C$5)*(TRANSAKSI_LOG!$J$2:$J$998=D$7)*(TRANSAKSI_LOG!$E$2:$E$998<=$B18)*(TRANSAKSI_LOG!$F$2:$F$998>=$B18),0),0)),"")} | E18: {=IFERROR(INDEX(TRANSAKSI_LOG!$M$2:$M$998,MATCH(1,INDEX((TRANSAKSI_LOG!$C$2:$C$998=$C$5)*(TRANSAKSI_LOG!$J$2:$J$998=E$7)*(TRANSAKSI_LOG!$E$2:$E$998<=$B18)*(TRANSAKSI_LOG!$F$2:$F$998>=$B18),0),0)) & " - " & INDEX(TRANSAKSI_LOG!$H$2:$H$998,MATCH(1,INDEX((TRANSAKSI_LOG!$C$2:$C$998=$C$5)*(TRANSAKSI_LOG!$J$2:$J$998=E$7)*(TRANSAKSI_LOG!$E$2:$E$998<=$B18)*(TRANSAKSI_LOG!$F$2:$F$998>=$B18),0),0)),"")} | F18: {=IFERROR(INDEX(TRANSAKSI_LOG!$M$2:$M$998,MATCH(1,INDEX((TRANSAKSI_LOG!$C$2:$C$998=$C$5)*(TRANSAKSI_LOG!$J$2:$J$998=F$7)*(TRANSAKSI_LOG!$E$2:$E$998<=$B18)*(TRANSAKSI_LOG!$F$2:$F$998>=$B18),0),0)) & " - " & INDEX(TRANSAKSI_LOG!$H$2:$H$998,MATCH(1,INDEX((TRANSAKSI_LOG!$C$2:$C$998=$C$5)*(TRANSAKSI_LOG!$J$2:$J$998=F$7)*(TRANSAKSI_LOG!$E$2:$E$998<=$B18)*(TRANSAKSI_LOG!$F$2:$F$998>=$B18),0),0)),"")} | G18: {=IFERROR(INDEX(TRANSAKSI_LOG!$M$2:$M$998,MATCH(1,INDEX((TRANSAKSI_LOG!$C$2:$C$998=$C$5)*(TRANSAKSI_LOG!$J$2:$J$998=G$7)*(TRANSAKSI_LOG!$E$2:$E$998<=$B18)*(TRANSAKSI_LOG!$F$2:$F$998>=$B18),0),0)) & " - " & INDEX(TRANSAKSI_LOG!$H$2:$H$998,MATCH(1,INDEX((TRANSAKSI_LOG!$C$2:$C$998=$C$5)*(TRANSAKSI_LOG!$J$2:$J$998=G$7)*(TRANSAKSI_LOG!$E$2:$E$998<=$B18)*(TRANSAKSI_LOG!$F$2:$F$998>=$B18),0),0)),"")} | H18: {=IFERROR(INDEX(TRANSAKSI_LOG!$M$2:$M$998,MATCH(1,INDEX((TRANSAKSI_LOG!$C$2:$C$998=$C$5)*(TRANSAKSI_LOG!$J$2:$J$998=H$7)*(TRANSAKSI_LOG!$E$2:$E$998<=$B18)*(TRANSAKSI_LOG!$F$2:$F$998>=$B18),0),0)) & " - " & INDEX(TRANSAKSI_LOG!$H$2:$H$998,MATCH(1,INDEX((TRANSAKSI_LOG!$C$2:$C$998=$C$5)*(TRANSAKSI_LOG!$J$2:$J$998=H$7)*(TRANSAKSI_LOG!$E$2:$E$998<=$B18)*(TRANSAKSI_LOG!$F$2:$F$998>=$B18),0),0)),"")}
B19: 0.37152778 | C19: {=IFERROR(INDEX(TRANSAKSI_LOG!$M$2:$M$998,MATCH(1,INDEX((TRANSAKSI_LOG!$C$2:$C$998=$C$5)*(TRANSAKSI_LOG!$J$2:$J$998=C$7)*(TRANSAKSI_LOG!$E$2:$E$998<=$B19)*(TRANSAKSI_LOG!$F$2:$F$998>=$B19),0),0)) & " - " & INDEX(TRANSAKSI_LOG!$H$2:$H$998,MATCH(1,INDEX((TRANSAKSI_LOG!$C$2:$C$998=$C$5)*(TRANSAKSI_LOG!$J$2:$J$998=C$7)*(TRANSAKSI_LOG!$E$2:$E$998<=$B19)*(TRANSAKSI_LOG!$F$2:$F$998>=$B19),0),0)),"")} | D19: {=IFERROR(INDEX(TRANSAKSI_LOG!$M$2:$M$998,MATCH(1,INDEX((TRANSAKSI_LOG!$C$2:$C$998=$C$5)*(TRANSAKSI_LOG!$J$2:$J$998=D$7)*(TRANSAKSI_LOG!$E$2:$E$998<=$B19)*(TRANSAKSI_LOG!$F$2:$F$998>=$B19),0),0)) & " - " & INDEX(TRANSAKSI_LOG!$H$2:$H$998,MATCH(1,INDEX((TRANSAKSI_LOG!$C$2:$C$998=$C$5)*(TRANSAKSI_LOG!$J$2:$J$998=D$7)*(TRANSAKSI_LOG!$E$2:$E$998<=$B19)*(TRANSAKSI_LOG!$F$2:$F$998>=$B19),0),0)),"")} | E19: {=IFERROR(INDEX(TRANSAKSI_LOG!$M$2:$M$998,MATCH(1,INDEX((TRANSAKSI_LOG!$C$2:$C$998=$C$5)*(TRANSAKSI_LOG!$J$2:$J$998=E$7)*(TRANSAKSI_LOG!$E$2:$E$998<=$B19)*(TRANSAKSI_LOG!$F$2:$F$998>=$B19),0),0)) & " - " & INDEX(TRANSAKSI_LOG!$H$2:$H$998,MATCH(1,INDEX((TRANSAKSI_LOG!$C$2:$C$998=$C$5)*(TRANSAKSI_LOG!$J$2:$J$998=E$7)*(TRANSAKSI_LOG!$E$2:$E$998<=$B19)*(TRANSAKSI_LOG!$F$2:$F$998>=$B19),0),0)),"")} | F19: {=IFERROR(INDEX(TRANSAKSI_LOG!$M$2:$M$998,MATCH(1,INDEX((TRANSAKSI_LOG!$C$2:$C$998=$C$5)*(TRANSAKSI_LOG!$J$2:$J$998=F$7)*(TRANSAKSI_LOG!$E$2:$E$998<=$B19)*(TRANSAKSI_LOG!$F$2:$F$998>=$B19),0),0)) & " - " & INDEX(TRANSAKSI_LOG!$H$2:$H$998,MATCH(1,INDEX((TRANSAKSI_LOG!$C$2:$C$998=$C$5)*(TRANSAKSI_LOG!$J$2:$J$998=F$7)*(TRANSAKSI_LOG!$E$2:$E$998<=$B19)*(TRANSAKSI_LOG!$F$2:$F$998>=$B19),0),0)),"")} | G19: {=IFERROR(INDEX(TRANSAKSI_LOG!$M$2:$M$998,MATCH(1,INDEX((TRANSAKSI_LOG!$C$2:$C$998=$C$5)*(TRANSAKSI_LOG!$J$2:$J$998=G$7)*(TRANSAKSI_LOG!$E$2:$E$998<=$B19)*(TRANSAKSI_LOG!$F$2:$F$998>=$B19),0),0)) & " - " & INDEX(TRANSAKSI_LOG!$H$2:$H$998,MATCH(1,INDEX((TRANSAKSI_LOG!$C$2:$C$998=$C$5)*(TRANSAKSI_LOG!$J$2:$J$998=G$7)*(TRANSAKSI_LOG!$E$2:$E$998<=$B19)*(TRANSAKSI_LOG!$F$2:$F$998>=$B19),0),0)),"")} | H19: {=IFERROR(INDEX(TRANSAKSI_LOG!$M$2:$M$998,MATCH(1,INDEX((TRANSAKSI_LOG!$C$2:$C$998=$C$5)*(TRANSAKSI_LOG!$J$2:$J$998=H$7)*(TRANSAKSI_LOG!$E$2:$E$998<=$B19)*(TRANSAKSI_LOG!$F$2:$F$998>=$B19),0),0)) & " - " & INDEX(TRANSAKSI_LOG!$H$2:$H$998,MATCH(1,INDEX((TRANSAKSI_LOG!$C$2:$C$998=$C$5)*(TRANSAKSI_LOG!$J$2:$J$998=H$7)*(TRANSAKSI_LOG!$E$2:$E$998<=$B19)*(TRANSAKSI_LOG!$F$2:$F$998>=$B19),0),0)),"")}
... B152: 0.83333333 | C152: {=IFERROR(INDEX(TRANSAKSI_LOG!$M$2:$M$998,MATCH(1,INDEX((TRANSAKSI_LOG!$C$2:$C$998=$C$5)*(TRANSAKSI_LOG!$J$2:$J$998=C$7)*(TRANSAKSI_LOG!$E$2:$E$998<=$B152)*(TRANSAKSI_LOG!$F$2:$F$998>=$B152),0),0)) & " - " & INDEX(TRANSAKSI_LOG!$H$2:$H$998,MATCH(1,INDEX((TRANSAKSI_LOG!$C$2:$C$998=$C$5)*(TRANSAKSI_LOG!$J$2:$J$998=C$7)*(TRANSAKSI_LOG!$E$2:$E$998<=$B152)*(TRANSAKSI_LOG!$F$2:$F$998>=$B152),0),0)),"")} | D152: {=IFERROR(INDEX(TRANSAKSI_LOG!$M$2:$M$998,MATCH(1,INDEX((TRANSAKSI_LOG!$C$2:$C$998=$C$5)*(TRANSAKSI_LOG!$J$2:$J$998=D$7)*(TRANSAKSI_LOG!$E$2:$E$998<=$B152)*(TRANSAKSI_LOG!$F$2:$F$998>=$B152),0),0)) & " - " & INDEX(TRANSAKSI_LOG!$H$2:$H$998,MATCH(1,INDEX((TRANSAKSI_LOG!$C$2:$C$998=$C$5)*(TRANSAKSI_LOG!$J$2:$J$998=D$7)*(TRANSAKSI_LOG!$E$2:$E$998<=$B152)*(TRANSAKSI_LOG!$F$2:$F$998>=$B152),0),0)),"")} | E152: {=IFERROR(INDEX(TRANSAKSI_LOG!$M$2:$M$998,MATCH(1,INDEX((TRANSAKSI_LOG!$C$2:$C$998=$C$5)*(TRANSAKSI_LOG!$J$2:$J$998=E$7)*(TRANSAKSI_LOG!$E$2:$E$998<=$B152)*(TRANSAKSI_LOG!$F$2:$F$998>=$B152),0),0)) & " - " & INDEX(TRANSAKSI_LOG!$H$2:$H$998,MATCH(1,INDEX((TRANSAKSI_LOG!$C$2:$C$998=$C$5)*(TRANSAKSI_LOG!$J$2:$J$998=E$7)*(TRANSAKSI_LOG!$E$2:$E$998<=$B152)*(TRANSAKSI_LOG!$F$2:$F$998>=$B152),0),0)),"")} | F152: {=IFERROR(INDEX(TRANSAKSI_LOG!$M$2:$M$998,MATCH(1,INDEX((TRANSAKSI_LOG!$C$2:$C$998=$C$5)*(TRANSAKSI_LOG!$J$2:$J$998=F$7)*(TRANSAKSI_LOG!$E$2:$E$998<=$B152)*(TRANSAKSI_LOG!$F$2:$F$998>=$B152),0),0)) & " - " & INDEX(TRANSAKSI_LOG!$H$2:$H$998,MATCH(1,INDEX((TRANSAKSI_LOG!$C$2:$C$998=$C$5)*(TRANSAKSI_LOG!$J$2:$J$998=F$7)*(TRANSAKSI_LOG!$E$2:$E$998<=$B152)*(TRANSAKSI_LOG!$F$2:$F$998>=$B152),0),0)),"")} | G152: {=IFERROR(INDEX(TRANSAKSI_LOG!$M$2:$M$998,MATCH(1,INDEX((TRANSAKSI_LOG!$C$2:$C$998=$C$5)*(TRANSAKSI_LOG!$J$2:$J$998=G$7)*(TRANSAKSI_LOG!$E$2:$E$998<=$B152)*(TRANSAKSI_LOG!$F$2:$F$998>=$B152),0),0)) & " - " & INDEX(TRANSAKSI_LOG!$H$2:$H$998,MATCH(1,INDEX((TRANSAKSI_LOG!$C$2:$C$998=$C$5)*(TRANSAKSI_LOG!$J$2:$J$998=G$7)*(TRANSAKSI_LOG!$E$2:$E$998<=$B152)*(TRANSAKSI_LOG!$F$2:$F$998>=$B152),0),0)),"")} | H152: {=IFERROR(INDEX(TRANSAKSI_LOG!$M$2:$M$998,MATCH(1,INDEX((TRANSAKSI_LOG!$C$2:$C$998=$C$5)*(TRANSAKSI_LOG!$J$2:$J$998=H$7)*(TRANSAKSI_LOG!$E$2:$E$998<=$B152)*(TRANSAKSI_LOG!$F$2:$F$998>=$B152),0),0)) & " - " & INDEX(TRANSAKSI_LOG!$H$2:$H$998,MATCH(1,INDEX((TRANSAKSI_LOG!$C$2:$C$998=$C$5)*(TRANSAKSI_LOG!$J$2:$J$998=H$7)*(TRANSAKSI_LOG!$E$2:$E$998<=$B152)*(TRANSAKSI_LOG!$F$2:$F$998>=$B152),0),0)),"")}

Sheet INVOICE
B1: DASHBOARD | D1: INPUT | F1: LOG | H1: CRM | J1: HARIAN | L1: BULANAN | N1: INVOICE | P1: JADWAL | R1: LOGIN
B4: No Invoice | C4: INV-BK-20260325-001
B5: Tanggal Cetak | C5: 46105.904
B6: Nama Customer | C6: jjhhjh
B7: Nama Anak | C7: lmlm
B8: Tanggal Booking | C8: 46106
B9: Jam Booking | C9: 0.625
B10: Layanan | C10: Newborn Starter Pack With Piercing (Paket Awal Kehidupan)
B11: Terapis | C11: Caccaca
B12: Harga | C12: 150000
B13: Diskon | C13: 0
B14: Transport | C14: 0
B15: Grand Total | C15: 150000
B16: Deposit | C16: 0
B17: Sisa Bayar | C17: 150000
B18: Status Bayar | C18: Belum Bayar

Sheet CRM PELANGGAN
A1: customer_id | B1: parent_name | C1: phone | D1: address | E1: child_name | F1: child_age | G1: visit_count | H1: total_spending | I1: avg_per_visit | J1: last_visit | K1: customer_type | L1: DASHBOARD | N1: INPUT | P1: LOG | R1: CRM | T1: HARIAN | V1: BULANAN | X1: INVOICE | Z1: JADWAL | AB1: LOGIN
A2: L0001 | B2: jjhhjh | C2: 545433423 | D2: 3e3e3 | E2: lmlm | F2: 1 Bulan | G2: 1 | H2: 150000 | I2: 150000 | J2: 25-3-2026 | K2: Baru
A3: L0002 | B3: dsdsds | C3: 897666555 | D3: 3r4r4t | E3: gghhggh | F3: 25 Tahun | G3: 1 | H3: 75000 | I3: 75000 | J3: 25-3-2026 | K3: Baru | L3: Oxytocin Stimulation Massage HC (Pijat Oksitosin)
A4: L0003 | B4: aqaq | C4: 213445432 | D4: yyuu7878 | E4: cvcv | F4: 12 Bulan | G4: 1 | H4: 60000 | I4: 60000 | J4: 25-3-2026 | K4: Baru | L4: Healthy Breath Package (Paket Nafas Sehat)
A5: L0004 | B5: rtrtrt | C5: 3455676690 | D5: jjkkk889 | E5: iuiuiu | F5: 12 Bulan | G5: 1 | H5: 85000 | I5: 85000 | J5: 26-3-2026 | K5: Baru

Sheet TRANSAKSI_LOG
A1: booking_id | B1: created_at | C1: booking_date | D1: month_name | E1: start_time | F1: end_time | G1: booking_type | H1: service_name | I1: service_category | J1: therapist_name | K1: parent_name | L1: phone | M1: child_name | N1: child_age | O1: address | P1: list_price | Q1: discount_code | R1: discount_value | S1: transport_area | T1: transport_fee | U1: grand_total | V1: deposit_amount | W1: remaining_balance | X1: payment_method | Y1: payment_status | Z1: booking_status | AA1: service_done_status | AB1: notes | AC1: therapist_fee | AD1: admin_fee | AE1: record_status | AF1: month_num | AG1: year_num | AJ1: DASHBOARD | AL1: INPUT | AN1: LOG | AP1: CRM | AR1: HARIAN | AT1: BULANAN | AV1: INVOICE | AX1: JADWAL | AZ1: LOGIN
A2: BK-20260325-001 | B2: 46106.481 | C2: 25-3-2026 | D2: Maret | E2: 0.625 | F2: 0.67361111 | G2: Inhouse | H2: Newborn Starter Pack With Piercing (Paket Awal Kehidupan) | I2: BABY | J2: Caccaca | K2: jjhhjh | L2: 545433423 | M2: lmlm | N2: 1 Bulan | O2: 3e3e3 | P2: 150000 | Q2: NONE | R2: 0 | S2: NONE | T2: 0 | U2: 150000 | V2: 0 | W2: 0 | X2: Qris | Y2: Lunas | Z2: Done | AA2: DONE | AC2: 40000 | AD2: 10000 | AE2: Active | AF2: 3 | AG2: 2026
A3: BK-20260325-002 | B3: 46106.485 | C3: 25-3-2026 | D3: Maret | E3: 0.47222222 | F3: 0.49305556 | G3: Homecare | H3: Oxytocin Stimulation Massage HC (Pijat Oksitosin) | I3: HOMECARE MOM | J3: ggagaga | K3: dsdsds | L3: 897666555 | M3: gghhggh | N3: 25 Tahun | O3: 3r4r4t | P3: 50000 | Q3: NONE | R3: 0 | S3: Zona Sedang | T3: 25000 | U3: 75000 | V3: 0 | W3: 0 | X3: Qris | Y3: Lunas | Z3: Done | AA3: DONE | AC3: 10000 | AD3: 5000 | AE3: Active | AF3: 3 | AG3: 2026
A4: BK-20260325-003 | B4: 46106.486 | C4: 25-3-2026 | D4: Maret | E4: 0.54861111 | F4: 0.56944444 | G4: Inhouse | H4: Healthy Breath Package (Paket Nafas Sehat) | I4: BABY | J4: bababab | K4: aqaq | L4: 213445432 | M4: cvcv | N4: 12 Bulan | O4: yyuu7878 | P4: 60000 | Q4: NONE | R4: 0 | S4: NONE | T4: 0 | U4: 60000 | V4: 0 | W4: 0 | X4: Qris | Y4: Lunas | Z4: Done | AA4: DONE | AC4: 10000 | AD4: 5000 | AE4: Active | AF4: 3 | AG4: 2026
A5: BK-20260326-004 | B5: 46108.364 | C5: 26-3-2026 | D5: Maret | E5: 0.375 | F5: 0.41666667 | G5: Inhouse | H5: Colic Relief Massage Baby (Pijat Kolik) | I5: BABY | J5: hahaha | K5: rtrtrt | L5: 3455676690 | M5: iuiuiu | N5: 12 Bulan | O5: jjkkk889 | P5: 85000 | Q5: NONE | R5: 0 | S5: NONE | T5: 0 | U5: 85000 | V5: 0 | W5: 0 | X5: Qris | Y5: Lunas | Z5: Done | AA5: DONE | AC5: 20000 | AD5: 10000 | AE5: Active | AF5: 3 | AG5: 2026

Sheet USER ACCESS
A1: email | B1: pin | C1: role | D1: display_name | E1: is_active | F1: notes
A2: puguh.legowo.k@gmail.com | B2: 1234 | C2: OWNER | D2: Owner Utama | E2: Y | F2: Ganti PIN setelah setup
A3: refinna.sari.86@gmail.com | B3: 4321 | C3: ADMIN | D3: Admin Frontdesk | E3: Y

Sheet STATUS MAP
A1: domain | B1: status_code | C1: label_id | D1: meaning | E1: owner_metric
A2: booking_status | B2: Active | C2: Active | D2: Booking aktif dan terjadwal | E2: booking_open
A3: booking_status | B3: Done | C3: Done | D3: Sesi selesai / closed by operation | E3: booking_done
A4: booking_status | B4: Cancelled | C4: Cancelled | D4: Dibatalkan | E4: booking_cancelled
A5: payment_status | B5: Belum Bayar | C5: Belum Bayar | D5: Belum ada pembayaran masuk | E5: ar_open
A6: payment_status | B6: DP | C6: DP | D6: Deposit masuk tetapi belum lunas | E6: ar_partial
A7: payment_status | B7: Lunas | C7: Lunas | D7: Tagihan selesai | E7: cash_closed
A8: service_done_status | B8: PENDING | C8: Pending | D8: Sesi belum dilaksanakan | E8: session_open
A9: service_done_status | B9: ONGOING | C9: On Going | D9: Sesi sedang berjalan | E9: session_live
A10: service_done_status | B10: DONE | C10: Done | D10: Sesi sudah selesai | E10: session_closed
A11: record_status | B11: Active | C11: Active | D11: Baris transaksi aktif | E11: included
A12: record_status | B12: Archived | C12: Archived | D12: Baris disimpan / tidak aktif | E12: excluded

Sheet REKAP HARIAN
A1: REKAP HARIAN | J1: DASHBOARD | L1: INPUT | N1: LOG | P1: CRM | R1: HARIAN | T1: BULANAN | V1: INVOICE | X1: JADWAL | Z1: LOGIN
B2: PILIH BULAN : | C2: PILIH TAHUN
B3: 3 | C3: 2026
A4: date | B4: total_booking | C4: homecare_count | D4: inhouse_count | E4: gross_revenue | F4: pending_payment | G4: done_count | H4: last_updated
A5: 1-3-2026 | B5: 0 | C5: 0 | D5: 0 | E5: 0 | F5: 0 | G5: 0 | H5: 27/03/2026 08:47
A6: 2-3-2026 | B6: 0 | C6: 0 | D6: 0 | E6: 0 | F6: 0 | G6: 0 | H6: 27/03/2026 08:47
A7: 3-3-2026 | B7: 0 | C7: 0 | D7: 0 | E7: 0 | F7: 0 | G7: 0 | H7: 27/03/2026 08:47
A8: 4-3-2026 | B8: 0 | C8: 0 | D8: 0 | E8: 0 | F8: 0 | G8: 0 | H8: 27/03/2026 08:47
A9: 5-3-2026 | B9: 0 | C9: 0 | D9: 0 | E9: 0 | F9: 0 | G9: 0 | H9: 27/03/2026 08:47
A10: 6-3-2026 | B10: 0 | C10: 0 | D10: 0 | E10: 0 | F10: 0 | G10: 0 | H10: 27/03/2026 08:47
A11: 7-3-2026 | B11: 0 | C11: 0 | D11: 0 | E11: 0 | F11: 0 | G11: 0 | H11: 27/03/2026 08:47
A12: 8-3-2026 | B12: 0 | C12: 0 | D12: 0 | E12: 0 | F12: 0 | G12: 0 | H12: 27/03/2026 08:47
A13: 9-3-2026 | B13: 0 | C13: 0 | D13: 0 | E13: 0 | F13: 0 | G13: 0 | H13: 27/03/2026 08:47
A14: 10-3-2026 | B14: 0 | C14: 0 | D14: 0 | E14: 0 | F14: 0 | G14: 0 | H14: 27/03/2026 08:47
A15: 11-3-2026 | B15: 0 | C15: 0 | D15: 0 | E15: 0 | F15: 0 | G15: 0 | H15: 27/03/2026 08:47
A16: 12-3-2026 | B16: 0 | C16: 0 | D16: 0 | E16: 0 | F16: 0 | G16: 0 | H16: 27/03/2026 08:47
... A35: 31-3-2026 | B35: 0 | C35: 0 | D35: 0 | E35: 0 | F35: 0 | G35: 0 | H35: 27/03/2026 08:47

Sheet REKAP BULANAN
A1: REKAP BULANAN | Q1: DASHBOARD | S1: INPUT | U1: LOG | W1: CRM | Y1: HARIAN | AA1: BULANAN | AC1: INVOICE | AE1: JADWAL | AG1: LOGIN
B2: PILIH TAHUN
B3: 2026
A4: month_name | B4: year_num | C4: total_booking | D4: homecare_count | E4: inhouse_count | F4: gross_revenue | G4: pending_payment | H4: done_count | I4: avg_ticket | J4: top_therapist | K4: top_therapist_qty | L4: total_service | M4: top_service | N4: top_service_qty | O4: last_updated
A5: Januari | B5: 2026 | C5: 0 | D5: 0 | E5: 0 | F5: 0 | G5: 0 | H5: 0 | I5: 0 | K5: 0 | L5: 0 | N5: 0 | O5: 27/03/2026 08:47
A6: Februari | B6: 2026 | C6: 0 | D6: 0 | E6: 0 | F6: 0 | G6: 0 | H6: 0 | I6: 0 | K6: 0 | L6: 0 | N6: 0 | O6: 27/03/2026 08:47
A7: Maret | B7: 2026 | C7: 4 | D7: 1 | E7: 3 | F7: 370000 | G7: 0 | H7: 4 | I7: 92500 | J7: bababab | K7: 1 | L7: 4 | M7: Colic Relief Massage Baby (Pijat Kolik) | N7: 1 | O7: 27/03/2026 08:47
A8: April | B8: 2026 | C8: 0 | D8: 0 | E8: 0 | F8: 0 | G8: 0 | H8: 0 | I8: 0 | K8: 0 | L8: 0 | N8: 0 | O8: 27/03/2026 08:47
A9: Mei | B9: 2026 | C9: 0 | D9: 0 | E9: 0 | F9: 0 | G9: 0 | H9: 0 | I9: 0 | K9: 0 | L9: 0 | N9: 0 | O9: 27/03/2026 08:47
A10: Juni | B10: 2026 | C10: 0 | D10: 0 | E10: 0 | F10: 0 | G10: 0 | H10: 0 | I10: 0 | K10: 0 | L10: 0 | N10: 0 | O10: 27/03/2026 08:47
A11: Juli | B11: 2026 | C11: 0 | D11: 0 | E11: 0 | F11: 0 | G11: 0 | H11: 0 | I11: 0 | K11: 0 | L11: 0 | N11: 0 | O11: 27/03/2026 08:47
A12: Agustus | B12: 2026 | C12: 0 | D12: 0 | E12: 0 | F12: 0 | G12: 0 | H12: 0 | I12: 0 | K12: 0 | L12: 0 | N12: 0 | O12: 27/03/2026 08:47
A13: September | B13: 2026 | C13: 0 | D13: 0 | E13: 0 | F13: 0 | G13: 0 | H13: 0 | I13: 0 | K13: 0 | L13: 0 | N13: 0 | O13: 27/03/2026 08:47
A14: Oktober | B14: 2026 | C14: 0 | D14: 0 | E14: 0 | F14: 0 | G14: 0 | H14: 0 | I14: 0 | K14: 0 | L14: 0 | N14: 0 | O14: 27/03/2026 08:47
A15: November | B15: 2026 | C15: 0 | D15: 0 | E15: 0 | F15: 0 | G15: 0 | H15: 0 | I15: 0 | K15: 0 | L15: 0 | N15: 0 | O15: 27/03/2026 08:47
A16: Desember | B16: 2026 | C16: 0 | D16: 0 | E16: 0 | F16: 0 | G16: 0 | H16: 0 | I16: 0 | K16: 0 | L16: 0 | N16: 0 | O16: 27/03/2026 08:47

Sheet KOMISI TERAPIS
A1: KOMISI TERAPIS
A2: PILIH BULAN : | B2: PILIH TAHUN
A3: 3 | B3: 2026
A4: therapist_code | B4: therapist_name | C4: total_booking | D4: service_fee_total | E4: transport_fee_total | F4: grand_incentive | G4: last_updated
A5: T001 | B5: bababab | C5: =IFNA(COUNTIFS(TRANSAKSI_LOG!J:J,B5,TRANSAKSI_LOG!Y:Y,"lunas",TRANSAKSI_LOG!AA:AA,"Done",TRANSAKSI_LOG!AF:AF,$A$3,TRANSAKSI_LOG!AG:AG,$B$3),0) -> 1 | D5: =IFNA(SUMIFS(TRANSAKSI_LOG!AC:AC,TRANSAKSI_LOG!J:J,B5,TRANSAKSI_LOG!Y:Y,"lunas",TRANSAKSI_LOG!AA:AA,"Done",TRANSAKSI_LOG!AF:AF,$A$3,TRANSAKSI_LOG!AG:AG,$B$3),0) -> 10000 | E5: =IFNA(SUMIFS(TRANSAKSI_LOG!T:T,TRANSAKSI_LOG!J:J,B5,TRANSAKSI_LOG!G:G,"Homecare",TRANSAKSI_LOG!Y:Y,"lunas",TRANSAKSI_LOG!AA:AA,"Done",TRANSAKSI_LOG!AF:AF,$A$3,TRANSAKSI_LOG!AG:AG,$B$3),0) -> 0 | F5: =D5+E5 -> 10000 | G5: 26/03/2026 22:36
A6: T002 | B6: Caccaca | C6: =IFNA(COUNTIFS(TRANSAKSI_LOG!J:J,B6,TRANSAKSI_LOG!Y:Y,"lunas",TRANSAKSI_LOG!AA:AA,"Done",TRANSAKSI_LOG!AF:AF,$A$3,TRANSAKSI_LOG!AG:AG,$B$3),0) -> 1 | D6: =IFNA(SUMIFS(TRANSAKSI_LOG!AC:AC,TRANSAKSI_LOG!J:J,B6,TRANSAKSI_LOG!Y:Y,"lunas",TRANSAKSI_LOG!AA:AA,"Done",TRANSAKSI_LOG!AF:AF,$A$3,TRANSAKSI_LOG!AG:AG,$B$3),0) -> 40000 | E6: =IFNA(SUMIFS(TRANSAKSI_LOG!T:T,TRANSAKSI_LOG!J:J,B6,TRANSAKSI_LOG!G:G,"Homecare",TRANSAKSI_LOG!Y:Y,"lunas",TRANSAKSI_LOG!AA:AA,"Done",TRANSAKSI_LOG!AF:AF,$A$3,TRANSAKSI_LOG!AG:AG,$B$3),0) -> 0 | F6: =D6+E6 -> 40000 | G6: 26/03/2026 22:36
A7: T003 | B7: ggagaga | C7: =IFNA(COUNTIFS(TRANSAKSI_LOG!J:J,B7,TRANSAKSI_LOG!Y:Y,"lunas",TRANSAKSI_LOG!AA:AA,"Done",TRANSAKSI_LOG!AF:AF,$A$3,TRANSAKSI_LOG!AG:AG,$B$3),0) -> 1 | D7: =IFNA(SUMIFS(TRANSAKSI_LOG!AC:AC,TRANSAKSI_LOG!J:J,B7,TRANSAKSI_LOG!Y:Y,"lunas",TRANSAKSI_LOG!AA:AA,"Done",TRANSAKSI_LOG!AF:AF,$A$3,TRANSAKSI_LOG!AG:AG,$B$3),0) -> 10000 | E7: =IFNA(SUMIFS(TRANSAKSI_LOG!T:T,TRANSAKSI_LOG!J:J,B7,TRANSAKSI_LOG!G:G,"Homecare",TRANSAKSI_LOG!Y:Y,"lunas",TRANSAKSI_LOG!AA:AA,"Done",TRANSAKSI_LOG!AF:AF,$A$3,TRANSAKSI_LOG!AG:AG,$B$3),0) -> 25000 | F7: =D7+E7 -> 35000 | G7: 46107.942
A8: T004 | B8: hahaha | C8: =IFNA(COUNTIFS(TRANSAKSI_LOG!J:J,B8,TRANSAKSI_LOG!Y:Y,"lunas",TRANSAKSI_LOG!AA:AA,"Done",TRANSAKSI_LOG!AF:AF,$A$3,TRANSAKSI_LOG!AG:AG,$B$3),0) -> 1 | D8: =IFNA(SUMIFS(TRANSAKSI_LOG!AC:AC,TRANSAKSI_LOG!J:J,B8,TRANSAKSI_LOG!Y:Y,"lunas",TRANSAKSI_LOG!AA:AA,"Done",TRANSAKSI_LOG!AF:AF,$A$3,TRANSAKSI_LOG!AG:AG,$B$3),0) -> 20000 | E8: =IFNA(SUMIFS(TRANSAKSI_LOG!T:T,TRANSAKSI_LOG!J:J,B8,TRANSAKSI_LOG!G:G,"Homecare",TRANSAKSI_LOG!Y:Y,"lunas",TRANSAKSI_LOG!AA:AA,"Done",TRANSAKSI_LOG!AF:AF,$A$3,TRANSAKSI_LOG!AG:AG,$B$3),0) -> 0 | F8: =D8+E8 -> 20000 | G8: 46107.942

Sheet KOMISI SA
A1: KOMISI TERAPIS
A2: PILIH BULAN : | B2: PILIH TAHUN
A3: 3 | B3: 2026
A4: SA_code | B4: SA_name | C4: total_booking | D4: service_fee_total | E4: transport_fee_total | F4: grand_incentive | G4: last_updated
A5: S001 | B5: fhfhfhf | C5: =IFNA(COUNTIFS(TRANSAKSI_LOG!AE:AE,"Active",TRANSAKSI_LOG!Y:Y,"lunas",TRANSAKSI_LOG!AA:AA,"Done",TRANSAKSI_LOG!AF:AF,$A$3,TRANSAKSI_LOG!AG:AG,$B$3),0) -> 4 | D5: =IFNA(SUMIFS(TRANSAKSI_LOG!AD:AD,TRANSAKSI_LOG!AE:AE,"Active",TRANSAKSI_LOG!Y:Y,"lunas",TRANSAKSI_LOG!AA:AA,"Done",TRANSAKSI_LOG!AF:AF,$A$3,TRANSAKSI_LOG!AG:AG,$B$3),0) -> 30000 | E5: =0 -> 0 | F5: =D5+E5 -> 30000 | G5: 25/03/2026 11:32

Sheet MASTER_LAYANAN
A1: service_code | B1: service_name | C1: service_category | D1: duration_min | E1: price | F1: therapist_fee | G1: admin_fee | H1: active | I1: notes
A2: B001 | B2: BABY | C2: Baby Relaxation Massage (Pijat Relaksasi Bayi) | D2: 45 | E2: 75000 | F2: 20 | G2: 5 | H2: YA | L2: =IFERROR(__xludf.DUMMYFUNCTION("FILTER(MASTER_LAYANAN!C2:C1000, MASTER_LAYANAN!H2:H1000 = ""Ya"")"),"Baby Relaxation Massage (Pijat Relaksasi Bayi)") -> Baby Relaxation Massage (Pijat Relaksasi Bayi)
A3: B002 | B3: BABY | C3: Warm Water Swim Therapy (Renang & Terapi Air Hangat) | D3: 15 | E3: 50000 | F3: 10 | G3: 5 | H3: YA | L3: =IFERROR(__xludf.DUMMYFUNCTION("""COMPUTED_VALUE"""),"Warm Water Swim Therapy (Renang & Terapi Air Hangat)") -> Warm Water Swim Therapy (Renang & Terapi Air Hangat)
A4: B003 | B4: BABY | C4: Basic Baby Gym (Gym Bayi Dasar) | D4: 5 | E4: 20000 | F4: 5 | G4: 2 | H4: YA | L4: =IFERROR(__xludf.DUMMYFUNCTION("""COMPUTED_VALUE"""),"Basic Baby Gym (Gym Bayi Dasar)") -> Basic Baby Gym (Gym Bayi Dasar)
A5: B004 | B5: BABY | C5: Baby Ball Gym (Gym Bola Bayi) | D5: 5 | E5: 20000 | F5: 5 | G5: 2 | H5: YA | L5: =IFERROR(__xludf.DUMMYFUNCTION("""COMPUTED_VALUE"""),"Baby Ball Gym (Gym Bola Bayi)") -> Baby Ball Gym (Gym Bola Bayi)
A6: B005 | B6: BABY | C6: Baby Sensory Bubble Bath (Mandi Busa Sensorik Bayi) | D6: 15 | E6: 50000 | F6: 10 | G6: 5 | H6: YA | L6: =IFERROR(__xludf.DUMMYFUNCTION("""COMPUTED_VALUE"""),"Baby Sensory Bubble Bath (Mandi Busa Sensorik Bayi)") -> Baby Sensory Bubble Bath (Mandi Busa Sensorik Bayi)
A7: B006 | B7: BABY | C7: Tuina Massage Baby (Pijat Tuina) | D7: 60 | E7: 85000 | F7: 20 | G7: 10 | H7: YA | L7: =IFERROR(__xludf.DUMMYFUNCTION("""COMPUTED_VALUE"""),"Tuina Massage Baby (Pijat Tuina)") -> Tuina Massage Baby (Pijat Tuina)
A8: B007 | B8: BABY | C8: Colic Relief Massage Baby (Pijat Kolik) | D8: 60 | E8: 85000 | F8: 20 | G8: 10 | H8: YA | L8: =IFERROR(__xludf.DUMMYFUNCTION("""COMPUTED_VALUE"""),"Colic Relief Massage Baby (Pijat Kolik)") -> Colic Relief Massage Baby (Pijat Kolik)
A9: B008 | B9: BABY | C9: Cough & Cold Massage Baby(Pijat Batuk & Pilek) | D9: 60 | E9: 85000 | F9: 20 | G9: 10 | H9: YA | L9: =IFERROR(__xludf.DUMMYFUNCTION("""COMPUTED_VALUE"""),"Cough & Cold Massage Baby(Pijat Batuk & Pilek)") -> Cough & Cold Massage Baby(Pijat Batuk & Pilek)
A10: B009 | B10: BABY | C10: Constipation Relief Massage Baby (Pijat Konstipasi) | D10: 60 | E10: 85000 | F10: 20 | G10: 10 | H10: YA | L10: =IFERROR(__xludf.DUMMYFUNCTION("""COMPUTED_VALUE"""),"Constipation Relief Massage Baby (Pijat Konstipasi)") -> Constipation Relief Massage Baby (Pijat Konstipasi)
A11: B010 | B11: BABY | C11: Baby Ear Piercing (Tindik Telinga Bayi) | D11: 5 | E11: 50000 | F11: 10 | G11: 5 | H11: YA | L11: =IFERROR(__xludf.DUMMYFUNCTION("""COMPUTED_VALUE"""),"Baby Ear Piercing (Tindik Telinga Bayi)") -> Baby Ear Piercing (Tindik Telinga Bayi)
A12: B011 | B12: BABY | C12: Baby Nail Trimming (Pemotongan Kuku Bayi) | D12: 5 | E12: 15000 | F12: 5 | G12: 2 | H12: YA | L12: =IFERROR(__xludf.DUMMYFUNCTION("""COMPUTED_VALUE"""),"Baby Nail Trimming (Pemotongan Kuku Bayi)") -> Baby Nail Trimming (Pemotongan Kuku Bayi)
A13: B012 | B13: BABY | C13: Newborn Head Shaving (Cukur Gundul Bayi) | D13: 15 | E13: 50000 | F13: 10 | G13: 5 | H13: YA | L13: =IFERROR(__xludf.DUMMYFUNCTION("""COMPUTED_VALUE"""),"Newborn Head Shaving (Cukur Gundul Bayi)") -> Newborn Head Shaving (Cukur Gundul Bayi)
A14: B013 | B14: BABY | C14: Basic Personal Hygiene (Perawatan Kebersihan Dasar) | D14: 15 | E14: 20000 | F14: 5 | G14: 2 | H14: YA | L14: =IFERROR(__xludf.DUMMYFUNCTION("""COMPUTED_VALUE"""),"Basic Personal Hygiene (Perawatan Kebersihan Dasar)") -> Basic Personal Hygiene (Perawatan Kebersihan Dasar)
A15: B014 | B15: BABY | C15: Baby Infrared Therapy (Terapi Infrared Bayi) | D15: 20 | E15: 50000 | F15: 10 | G15: 5 | H15: YA | L15: =IFERROR(__xludf.DUMMYFUNCTION("""COMPUTED_VALUE"""),"Baby Infrared Therapy (Terapi Infrared Bayi)") -> Baby Infrared Therapy (Terapi Infrared Bayi)
A16: B015 | B16: BABY | C16: Baby Nebulizer Therapy (Terapi Nebulizer Bayi) | D16: 10 | E16: 50000 | F16: 10 | G16: 5 | H16: YA | L16: =IFERROR(__xludf.DUMMYFUNCTION("""COMPUTED_VALUE"""),"Baby Nebulizer Therapy (Terapi Nebulizer Bayi)") -> Baby Nebulizer Therapy (Terapi Nebulizer Bayi)
A17: B016 | B17: BABY | C17: Newborn Starter Pack With Piercing (Paket Awal Kehidupan) | D17: 70 | E17: 150000 | F17: 40 | G17: 10 | H17: YA | L17: =IFERROR(__xludf.DUMMYFUNCTION("""COMPUTED_VALUE"""),"Newborn Starter Pack With Piercing (Paket Awal Kehidupan)") -> Newborn Starter Pack With Piercing (Paket Awal Kehidupan)
A18: B017 | B18: BABY | C18: Newborn Starter Pack Without Piercing (Paket Awal Kehidupan) | D18: 70 | E18: 120000 | F18: 35 | G18: 10 | H18: YA | L18: =IFERROR(__xludf.DUMMYFUNCTION("""COMPUTED_VALUE"""),"Newborn Starter Pack Without Piercing (Paket Awal Kehidupan)") -> Newborn Starter Pack Without Piercing (Paket Awal Kehidupan)
A19: B018 | B19: BABY | C19: Optimal Energy Package (Paket Energi Optimal) | D19: 60 | E19: 125000 | F19: 35 | G19: 10 | H19: YA | L19: =IFERROR(__xludf.DUMMYFUNCTION("""COMPUTED_VALUE"""),"Optimal Energy Package (Paket Energi Optimal)") -> Optimal Energy Package (Paket Energi Optimal)
A20: B019 | B20: BABY | C20: Touch of Love Package (Paket Sentuh Cinta) | D20: 60 | E20: 90000 | F20: 20 | G20: 10 | H20: YA | L20: =IFERROR(__xludf.DUMMYFUNCTION("""COMPUTED_VALUE"""),"Touch of Love Package (Paket Sentuh Cinta)") -> Touch of Love Package (Paket Sentuh Cinta)
A21: B020 | B21: BABY | C21: Clear Breath Premium (Paket Nafas Lega) | D21: 60 | E21: 145000 | F21: 35 | G21: 10 | H21: YA | L21: =IFERROR(__xludf.DUMMYFUNCTION("""COMPUTED_VALUE"""),"Clear Breath Premium (Paket Nafas Lega)") -> Clear Breath Premium (Paket Nafas Lega)
A22: B021 | B22: BABY | C22: Clear Breath Premium WITHOUT UAP (Paket Nafas Lega Tanpa Uap) | D22: 60 | E22: 125000 | F22: 35 | G22: 10 | H22: YA | L22: =IFERROR(__xludf.DUMMYFUNCTION("""COMPUTED_VALUE"""),"Clear Breath Premium WITHOUT UAP (Paket Nafas Lega Tanpa Uap)") -> Clear Breath Premium WITHOUT UAP (Paket Nafas Lega Tanpa Uap)
A23: B022 | B23: BABY | C23: Healthy Breath Package (Paket Nafas Sehat) | D23: 30 | E23: 60000 | F23: 10 | G23: 5 | H23: YA | L23: =IFERROR(__xludf.DUMMYFUNCTION("""COMPUTED_VALUE"""),"Healthy Breath Package (Paket Nafas Sehat)") -> Healthy Breath Package (Paket Nafas Sehat)
A24: B023 | B24: BABY | C24: Healthy Breath Package 2x (Paket Nafas Sehat) | D24: 30 | E24: 100000 | F24: 40 | G24: 10 | H24: YA | L24: =IFERROR(__xludf.DUMMYFUNCTION("""COMPUTED_VALUE"""),"Healthy Breath Package 2x (Paket Nafas Sehat)") -> Healthy Breath Package 2x (Paket Nafas Sehat)
A25: K001 | B25: KID | C25: Kids Massage (Pijat Anak) | D25: 45 | E25: 80000 | F25: 20 | G25: 10 | H25: YA | L25: =IFERROR(__xludf.DUMMYFUNCTION("""COMPUTED_VALUE"""),"Kids Massage (Pijat Anak)") -> Kids Massage (Pijat Anak)
A26: K002 | B26: KID | C26: Kids Body Scrub (Lulur Anak) | D26: 30 | E26: 40000 | F26: 10 | G26: 5 | H26: YA | L26: =IFERROR(__xludf.DUMMYFUNCTION("""COMPUTED_VALUE"""),"Kids Body Scrub (Lulur Anak)") -> Kids Body Scrub (Lulur Anak)
A27: K004 | B27: KID | C27: Kid Sensory Bubble Bath (Mandi Busa Sensorik Anak) | D27: 15 | E27: 40000 | F27: 10 | G27: 5 | H27: YA | L27: =IFERROR(__xludf.DUMMYFUNCTION("""COMPUTED_VALUE"""),"Kid Sensory Bubble Bath (Mandi Busa Sensorik Anak)") -> Kid Sensory Bubble Bath (Mandi Busa Sensorik Anak)
A28: K003 | B28: KID | C28: Kids Facial Mask (Masker Muka) | D28: 15 | E28: 20000 | F28: 5 | G28: 2 | H28: YA | L28: =IFERROR(__xludf.DUMMYFUNCTION("""COMPUTED_VALUE"""),"Kids Facial Mask (Masker Muka)") -> Kids Facial Mask (Masker Muka)
